Workbook

Sheet دليل الاستخدام
A1: نظام إدارة بنود عقد البوابة الموحدة
A2: دليل الاستخدام
A5: طريقة العمل
A6: 1) شيت «الإعدادات»: بيانات العقد، نسبة الضريبة، مهلة المراجعة، والإجازة الأسبوعية.
A7: 2) شيت «البنود»: كل بند تعاقدي في صف — الرقم، WBS، الاسم، الكمية، سعر الوحدة.
A8: 3) شيت «المخرجات»: صف لكل مخرج تحت البند بتاعه، برقم ثابت (D-001، D-002، ...).
A9: 4) شيت «سجل المراجعات»: كل ما يحصل تسليم أو رد بملاحظات أو قبول، ضيف صف جديد بالتاريخ.
A10: 5) شيت «الأجازات»: أي إجازة رسمية جديدة تضاف هنا عشان تتشال من حساب الأيام.
A12: ألوان الخلايا
A13: رأس عمود أزرق = عمود إدخال، اكتب فيه.
A14: رأس عمود رمادي وخلفية رمادية = معادلة، متكتبش فيه.
A15: حط الماوس على رأس أي عمود عليه مثلث أحمر صغير عشان تشوف شرح المعادلة.
... A36: D-005 | قبول | 2026-04-12

Sheet الإعدادات
A1: الإعدادات وبيانات العقد
A2: الخلايا البيضاء للإدخال — الرمادية محسوبة تلقائياً
A4: البيان | B4: القيمة | C4: ملاحظة
A5: اسم المشروع | B5: مشروع تجريبي
A6: رقم العقد / كود المشروع | B6: CX-0000-0000
A7: الجهة المالكة | B7: الجهة المالكة (مثال)
A8: المورد / المنفذ | B8: المورد (مثال)
A9: تاريخ بداية العقد | B9: 45658
A10: مدة العقد (بالأشهر) | B10: 24
A11: تاريخ نهاية العقد | B11: =IF(ISNUMBER(B9),EDATE(B9,B10)-1,"") -> 46387 | C11: تاريخ البداية + المدة بالأشهر − يوم
A12: نسبة ضريبة القيمة المضافة | B12: 0.15
A13: مهلة المراجعة (أيام عمل) | B13: 10 | C13: عدد أيام العمل المسموح بها للرد على كل تسليم. أي يوم زيادة يُحسب تأخير.
A14: رمز الإجازة الأسبوعية | B14: 7 | C14: رمز Excel لأيام الإجازة الأسبوعية في دالة NETWORKDAYS.INTL: — 7 = الجمعة والسبت — 1 = السبت والأحد — 16 = الجمعة فقط
A15: تاريخ احتساب ثابت (اختياري) | B15: 46203 | C15: اتركه فارغاً ليتم الحساب حتى تاريخ اليوم. — اكتب تاريخاً لو عايز تطلع تقرير "كما في تاريخ معين".
A16: تاريخ الاحتساب الفعلي | B16: =IF(ISNUMBER(B15),B15,TODAY()) -> 46203 | C16: لو في تاريخ ثابت يُستخدم، وإلا تاريخ اليوم

Sheet البنود
A1: بنود العقد
A2: أدخل البنود كما في جدول الكميات — كل الأعمدة الرمادية محسوبة من شيت المخرجات
C3: الإجمالي | D3: =SUM(D5:D44) -> 9 | F3: =SUM(F5:F44) -> 3900000 | G3: =SUM(G5:G44) -> 585000 | H3: =SUM(H5:H44) -> 4485000 | I3: =SUM(I5:I44) -> 9 | J3: =SUM(J5:J44) -> 5 | K3: =SUM(K5:K44) -> 2 | L3: =SUM(L5:L44) -> 1 | M3: =IF(SUM(F5:F44)=0,"",SUM(N5:N44)/SUM(F5:F44)) -> 0.051282051 | N3: =SUM(N5:N44) -> 200000 | O3: =SUM(O5:O44) -> 3700000
A4: رقم البند | B4: WBS | C4: اسم البند | D4: الكمية التعاقدية | E4: سعر الوحدة (قبل الضريبة) | F4: الإجمالي قبل الضريبة | G4: الضريبة | H4: الإجمالي شامل الضريبة | I4: المخرجات المسجلة | J4: المسلّمة | K4: المقبولة | L4: المتأخرة | M4: نسبة الإنجاز | N4: قيمة المقبول (قبل الضريبة) | O4: المتبقي (قبل الضريبة)
A5: 1 | B5: CX-0000-0000-001 | C5: إعداد خطة المشروع | D5: 2 | E5: 100000 | F5: =IF(A5="","",D5*E5) -> 200000 | G5: =IF(A5="","",F5*نسبة_الضريبة) -> 30000 | H5: =IF(A5="","",F5+G5) -> 230000 | I5: =IF(A5="","",COUNTIF(المخرجات!$B$5:$B$404,A5)) -> 2 | J5: =IF(A5="","",COUNTIFS(المخرجات!$B$5:$B$404,A5,المخرجات!$J$5:$J$404,">0")) -> 2 | K5: =IF(A5="","",COUNTIFS(المخرجات!$B$5:$B$404,A5,المخرجات!$O$5:$O$404,"تم القبول")) -> 2 | L5: =IF(A5="","",COUNTIFS(المخرجات!$B$5:$B$404,A5,المخرجات!$O$5:$O$404,"متأخر")) -> 0 | M5: =IF(OR(A5="",N(D5)=0),"",K5/D5) -> 1 | N5: =IF(A5="","",K5*E5) -> 200000 | O5: =IF(A5="","",F5-N5) -> 0
A6: 2 | B6: CX-0000-0000-002 | C6: تحليل المتطلبات | D6: 4 | E6: 250000 | F6: =IF(A6="","",D6*E6) -> 1000000 | G6: =IF(A6="","",F6*نسبة_الضريبة) -> 150000 | H6: =IF(A6="","",F6+G6) -> 1150000 | I6: =IF(A6="","",COUNTIF(المخرجات!$B$5:$B$404,A6)) -> 4 | J6: =IF(A6="","",COUNTIFS(المخرجات!$B$5:$B$404,A6,المخرجات!$J$5:$J$404,">0")) -> 2 | K6: =IF(A6="","",COUNTIFS(المخرجات!$B$5:$B$404,A6,المخرجات!$O$5:$O$404,"تم القبول")) -> 0 | L6: =IF(A6="","",COUNTIFS(المخرجات!$B$5:$B$404,A6,المخرجات!$O$5:$O$404,"متأخر")) -> 1 | M6: =IF(OR(A6="",N(D6)=0),"",K6/D6) -> 0 | N6: =IF(A6="","",K6*E6) -> 0 | O6: =IF(A6="","",F6-N6) -> 1000000
A7: 3.أ | B7: CX-0000-0000-003 | C7: تطوير الخدمات | D7: 3 | E7: 900000 | F7: =IF(A7="","",D7*E7) -> 2700000 | G7: =IF(A7="","",F7*نسبة_الضريبة) -> 405000 | H7: =IF(A7="","",F7+G7) -> 3105000 | I7: =IF(A7="","",COUNTIF(المخرجات!$B$5:$B$404,A7)) -> 3 | J7: =IF(A7="","",COUNTIFS(المخرجات!$B$5:$B$404,A7,المخرجات!$J$5:$J$404,">0")) -> 1 | K7: =IF(A7="","",COUNTIFS(المخرجات!$B$5:$B$404,A7,المخرجات!$O$5:$O$404,"تم القبول")) -> 0 | L7: =IF(A7="","",COUNTIFS(المخرجات!$B$5:$B$404,A7,المخرجات!$O$5:$O$404,"متأخر")) -> 0 | M7: =IF(OR(A7="",N(D7)=0),"",K7/D7) -> 0 | N7: =IF(A7="","",K7*E7) -> 0 | O7: =IF(A7="","",F7-N7) -> 2700000
F8: =IF(A8="","",D8*E8) | G8: =IF(A8="","",F8*نسبة_الضريبة) | H8: =IF(A8="","",F8+G8) | I8: =IF(A8="","",COUNTIF(المخرجات!$B$5:$B$404,A8)) | J8: =IF(A8="","",COUNTIFS(المخرجات!$B$5:$B$404,A8,المخرجات!$J$5:$J$404,">0")) | K8: =IF(A8="","",COUNTIFS(المخرجات!$B$5:$B$404,A8,المخرجات!$O$5:$O$404,"تم القبول")) | L8: =IF(A8="","",COUNTIFS(المخرجات!$B$5:$B$404,A8,المخرجات!$O$5:$O$404,"متأخر")) | M8: =IF(OR(A8="",N(D8)=0),"",K8/D8) | N8: =IF(A8="","",K8*E8) | O8: =IF(A8="","",F8-N8)
F9: =IF(A9="","",D9*E9) | G9: =IF(A9="","",F9*نسبة_الضريبة) | H9: =IF(A9="","",F9+G9) | I9: =IF(A9="","",COUNTIF(المخرجات!$B$5:$B$404,A9)) | J9: =IF(A9="","",COUNTIFS(المخرجات!$B$5:$B$404,A9,المخرجات!$J$5:$J$404,">0")) | K9: =IF(A9="","",COUNTIFS(المخرجات!$B$5:$B$404,A9,المخرجات!$O$5:$O$404,"تم القبول")) | L9: =IF(A9="","",COUNTIFS(المخرجات!$B$5:$B$404,A9,المخرجات!$O$5:$O$404,"متأخر")) | M9: =IF(OR(A9="",N(D9)=0),"",K9/D9) | N9: =IF(A9="","",K9*E9) | O9: =IF(A9="","",F9-N9)
F10: =IF(A10="","",D10*E10) | G10: =IF(A10="","",F10*نسبة_الضريبة) | H10: =IF(A10="","",F10+G10) | I10: =IF(A10="","",COUNTIF(المخرجات!$B$5:$B$404,A10)) | J10: =IF(A10="","",COUNTIFS(المخرجات!$B$5:$B$404,A10,المخرجات!$J$5:$J$404,">0")) | K10: =IF(A10="","",COUNTIFS(المخرجات!$B$5:$B$404,A10,المخرجات!$O$5:$O$404,"تم القبول")) | L10: =IF(A10="","",COUNTIFS(المخرجات!$B$5:$B$404,A10,المخرجات!$O$5:$O$404,"متأخر")) | M10: =IF(OR(A10="",N(D10)=0),"",K10/D10) | N10: =IF(A10="","",K10*E10) | O10: =IF(A10="","",F10-N10)
F11: =IF(A11="","",D11*E11) | G11: =IF(A11="","",F11*نسبة_الضريبة) | H11: =IF(A11="","",F11+G11) | I11: =IF(A11="","",COUNTIF(المخرجات!$B$5:$B$404,A11)) | J11: =IF(A11="","",COUNTIFS(المخرجات!$B$5:$B$404,A11,المخرجات!$J$5:$J$404,">0")) | K11: =IF(A11="","",COUNTIFS(المخرجات!$B$5:$B$404,A11,المخرجات!$O$5:$O$404,"تم القبول")) | L11: =IF(A11="","",COUNTIFS(المخرجات!$B$5:$B$404,A11,المخرجات!$O$5:$O$404,"متأخر")) | M11: =IF(OR(A11="",N(D11)=0),"",K11/D11) | N11: =IF(A11="","",K11*E11) | O11: =IF(A11="","",F11-N11)
F12: =IF(A12="","",D12*E12) | G12: =IF(A12="","",F12*نسبة_الضريبة) | H12: =IF(A12="","",F12+G12) | I12: =IF(A12="","",COUNTIF(المخرجات!$B$5:$B$404,A12)) | J12: =IF(A12="","",COUNTIFS(المخرجات!$B$5:$B$404,A12,المخرجات!$J$5:$J$404,">0")) | K12: =IF(A12="","",COUNTIFS(المخرجات!$B$5:$B$404,A12,المخرجات!$O$5:$O$404,"تم القبول")) | L12: =IF(A12="","",COUNTIFS(المخرجات!$B$5:$B$404,A12,المخرجات!$O$5:$O$404,"متأخر")) | M12: =IF(OR(A12="",N(D12)=0),"",K12/D12) | N12: =IF(A12="","",K12*E12) | O12: =IF(A12="","",F12-N12)
F13: =IF(A13="","",D13*E13) | G13: =IF(A13="","",F13*نسبة_الضريبة) | H13: =IF(A13="","",F13+G13) | I13: =IF(A13="","",COUNTIF(المخرجات!$B$5:$B$404,A13)) | J13: =IF(A13="","",COUNTIFS(المخرجات!$B$5:$B$404,A13,المخرجات!$J$5:$J$404,">0")) | K13: =IF(A13="","",COUNTIFS(المخرجات!$B$5:$B$404,A13,المخرجات!$O$5:$O$404,"تم القبول")) | L13: =IF(A13="","",COUNTIFS(المخرجات!$B$5:$B$404,A13,المخرجات!$O$5:$O$404,"متأخر")) | M13: =IF(OR(A13="",N(D13)=0),"",K13/D13) | N13: =IF(A13="","",K13*E13) | O13: =IF(A13="","",F13-N13)
F14: =IF(A14="","",D14*E14) | G14: =IF(A14="","",F14*نسبة_الضريبة) | H14: =IF(A14="","",F14+G14) | I14: =IF(A14="","",COUNTIF(المخرجات!$B$5:$B$404,A14)) | J14: =IF(A14="","",COUNTIFS(المخرجات!$B$5:$B$404,A14,المخرجات!$J$5:$J$404,">0")) | K14: =IF(A14="","",COUNTIFS(المخرجات!$B$5:$B$404,A14,المخرجات!$O$5:$O$404,"تم القبول")) | L14: =IF(A14="","",COUNTIFS(المخرجات!$B$5:$B$404,A14,المخرجات!$O$5:$O$404,"متأخر")) | M14: =IF(OR(A14="",N(D14)=0),"",K14/D14) | N14: =IF(A14="","",K14*E14) | O14: =IF(A14="","",F14-N14)
F15: =IF(A15="","",D15*E15) | G15: =IF(A15="","",F15*نسبة_الضريبة) | H15: =IF(A15="","",F15+G15) | I15: =IF(A15="","",COUNTIF(المخرجات!$B$5:$B$404,A15)) | J15: =IF(A15="","",COUNTIFS(المخرجات!$B$5:$B$404,A15,المخرجات!$J$5:$J$404,">0")) | K15: =IF(A15="","",COUNTIFS(المخرجات!$B$5:$B$404,A15,المخرجات!$O$5:$O$404,"تم القبول")) | L15: =IF(A15="","",COUNTIFS(المخرجات!$B$5:$B$404,A15,المخرجات!$O$5:$O$404,"متأخر")) | M15: =IF(OR(A15="",N(D15)=0),"",K15/D15) | N15: =IF(A15="","",K15*E15) | O15: =IF(A15="","",F15-N15)
F16: =IF(A16="","",D16*E16) | G16: =IF(A16="","",F16*نسبة_الضريبة) | H16: =IF(A16="","",F16+G16) | I16: =IF(A16="","",COUNTIF(المخرجات!$B$5:$B$404,A16)) | J16: =IF(A16="","",COUNTIFS(المخرجات!$B$5:$B$404,A16,المخرجات!$J$5:$J$404,">0")) | K16: =IF(A16="","",COUNTIFS(المخرجات!$B$5:$B$404,A16,المخرجات!$O$5:$O$404,"تم القبول")) | L16: =IF(A16="","",COUNTIFS(المخرجات!$B$5:$B$404,A16,المخرجات!$O$5:$O$404,"متأخر")) | M16: =IF(OR(A16="",N(D16)=0),"",K16/D16) | N16: =IF(A16="","",K16*E16) | O16: =IF(A16="","",F16-N16)
F17: =IF(A17="","",D17*E17) | G17: =IF(A17="","",F17*نسبة_الضريبة) | H17: =IF(A17="","",F17+G17) | I17: =IF(A17="","",COUNTIF(المخرجات!$B$5:$B$404,A17)) | J17: =IF(A17="","",COUNTIFS(المخرجات!$B$5:$B$404,A17,المخرجات!$J$5:$J$404,">0")) | K17: =IF(A17="","",COUNTIFS(المخرجات!$B$5:$B$404,A17,المخرجات!$O$5:$O$404,"تم القبول")) | L17: =IF(A17="","",COUNTIFS(المخرجات!$B$5:$B$404,A17,المخرجات!$O$5:$O$404,"متأخر")) | M17: =IF(OR(A17="",N(D17)=0),"",K17/D17) | N17: =IF(A17="","",K17*E17) | O17: =IF(A17="","",F17-N17)
F18: =IF(A18="","",D18*E18) | G18: =IF(A18="","",F18*نسبة_الضريبة) | H18: =IF(A18="","",F18+G18) | I18: =IF(A18="","",COUNTIF(المخرجات!$B$5:$B$404,A18)) | J18: =IF(A18="","",COUNTIFS(المخرجات!$B$5:$B$404,A18,المخرجات!$J$5:$J$404,">0")) | K18: =IF(A18="","",COUNTIFS(المخرجات!$B$5:$B$404,A18,المخرجات!$O$5:$O$404,"تم القبول")) | L18: =IF(A18="","",COUNTIFS(المخرجات!$B$5:$B$404,A18,المخرجات!$O$5:$O$404,"متأخر")) | M18: =IF(OR(A18="",N(D18)=0),"",K18/D18) | N18: =IF(A18="","",K18*E18) | O18: =IF(A18="","",F18-N18)
F19: =IF(A19="","",D19*E19) | G19: =IF(A19="","",F19*نسبة_الضريبة) | H19: =IF(A19="","",F19+G19) | I19: =IF(A19="","",COUNTIF(المخرجات!$B$5:$B$404,A19)) | J19: =IF(A19="","",COUNTIFS(المخرجات!$B$5:$B$404,A19,المخرجات!$J$5:$J$404,">0")) | K19: =IF(A19="","",COUNTIFS(المخرجات!$B$5:$B$404,A19,المخرجات!$O$5:$O$404,"تم القبول")) | L19: =IF(A19="","",COUNTIFS(المخرجات!$B$5:$B$404,A19,المخرجات!$O$5:$O$404,"متأخر")) | M19: =IF(OR(A19="",N(D19)=0),"",K19/D19) | N19: =IF(A19="","",K19*E19) | O19: =IF(A19="","",F19-N19)
... F44: =IF(A44="","",D44*E44) | G44: =IF(A44="","",F44*نسبة_الضريبة) | H44: =IF(A44="","",F44+G44) | I44: =IF(A44="","",COUNTIF(المخرجات!$B$5:$B$404,A44)) | J44: =IF(A44="","",COUNTIFS(المخرجات!$B$5:$B$404,A44,المخرجات!$J$5:$J$404,">0")) | K44: =IF(A44="","",COUNTIFS(المخرجات!$B$5:$B$404,A44,المخرجات!$O$5:$O$404,"تم القبول")) | L44: =IF(A44="","",COUNTIFS(المخرجات!$B$5:$B$404,A44,المخرجات!$O$5:$O$404,"متأخر")) | M44: =IF(OR(A44="",N(D44)=0),"",K44/D44) | N44: =IF(A44="","",K44*E44) | O44: =IF(A44="","",F44-N44)

Sheet المخرجات
A1: مخرجات العقد
A2: صف لكل مخرج — التواريخ والحالة والأيام بتتحسب من سجل المراجعات | F2: الرقم التالي المقترح: | G2: ="D-"&TEXT(COUNTA(A5:A404)+1,"000") -> D-010
A4: رقم المخرج | B4: رقم البند | C4: اسم البند | D4: وصف المخرج | E4: تاريخ التسليم المخطط | F4: حالة العمل (يدوي) | G4: النقاط المنجزة | H4: القيمة قبل الضريبة | I4: القيمة شامل الضريبة | J4: أول تسليم | K4: آخر تسليم | L4: آخر رد بملاحظات | M4: تاريخ القبول | N4: عدد مرات التسليم | O4: الحالة | P4: أيام المراجعة | Q4: أيام التأخير في القبول | R4: أيام تأخير التسليم | S4: ملاحظات
A5: D-001 | B5: 1 | C5: =IF($A5="","",IFERROR(INDEX(بند_الاسم,MATCH($B5,قائمة_البنود,0)),"⚠ بند غير موجود")) -> إعداد خطة المشروع | D5: وثيقة ميثاق المشروع | H5: =IF($A5="","",IFERROR(INDEX(بند_سعر_الوحدة,MATCH($B5,قائمة_البنود,0)),0)) -> 100000 | I5: =IF($A5="","",H5*(1+نسبة_الضريبة)) -> 115000 | J5: =IF($A5="","",_xlfn.MINIFS('سجل المراجعات'!$E$5:$E$1504,'سجل المراجعات'!$A$5:$A$1504,$A5,'سجل المراجعات'!$D$5:$D$1504,"تسليم")) -> 45698 | K5: =IF($A5="","",_xlfn.MAXIFS('سجل المراجعات'!$E$5:$E$1504,'سجل المراجعات'!$A$5:$A$1504,$A5,'سجل المراجعات'!$D$5:$D$1504,"تسليم")) -> 45698 | L5: =IF($A5="","",_xlfn.MAXIFS('سجل المراجعات'!$E$5:$E$1504,'سجل المراجعات'!$A$5:$A$1504,$A5,'سجل المراجعات'!$D$5:$D$1504,"رد بملاحظات")) -> 0 | M5: =IF($A5="","",_xlfn.MAXIFS('سجل المراجعات'!$E$5:$E$1504,'سجل المراجعات'!$A$5:$A$1504,$A5,'سجل المراجعات'!$D$5:$D$1504,"قبول")) -> 45705 | N5: =IF($A5="","",COUNTIFS('سجل المراجعات'!$A$5:$A$1504,$A5,'سجل المراجعات'!$D$5:$D$1504,"تسليم")) -> 1 | O5: =IF($A5="","",IF(M5>0,"تم القبول",IF(F5="معلق","معلق",IF(AND(L5>0,L5>=K5),"مُعاد بملاحظات",IF(K5>0,"في انتظار القبول",IF(AND(ISNUMBER(E5),E5<تاريخ_الاحتساب),"متأخر",IF(F5="","لم يبدأ",F5))))))) -> تم القبول | P5: =IF($A5="","",SUMIFS('سجل المراجعات'!$L$5:$L$1504,'سجل المراجعات'!$A$5:$A$1504,$A5)) -> 5 | Q5: =IF($A5="","",SUMIFS('سجل المراجعات'!$M$5:$M$1504,'سجل المراجعات'!$A$5:$A$1504,$A5)) -> 0 | R5: =IF(OR($A5="",NOT(ISNUMBER(E5))),"",MAX(0,NETWORKDAYS.INTL(E5,IF(J5>0,J5,تاريخ_الاحتساب),رمز_العطلة,أيام_الأجازات)-1))
A6: D-002 | B6: 1 | C6: =IF($A6="","",IFERROR(INDEX(بند_الاسم,MATCH($B6,قائمة_البنود,0)),"⚠ بند غير موجود")) -> إعداد خطة المشروع | D6: الخطة التفصيلية للمشروع | H6: =IF($A6="","",IFERROR(INDEX(بند_سعر_الوحدة,MATCH($B6,قائمة_البنود,0)),0)) -> 100000 | I6: =IF($A6="","",H6*(1+نسبة_الضريبة)) -> 115000 | J6: =IF($A6="","",_xlfn.MINIFS('سجل المراجعات'!$E$5:$E$1504,'سجل المراجعات'!$A$5:$A$1504,$A6,'سجل المراجعات'!$D$5:$D$1504,"تسليم")) -> 45698 | K6: =IF($A6="","",_xlfn.MAXIFS('سجل المراجعات'!$E$5:$E$1504,'سجل المراجعات'!$A$5:$A$1504,$A6,'سجل المراجعات'!$D$5:$D$1504,"تسليم")) -> 45728 | L6: =IF($A6="","",_xlfn.MAXIFS('سجل المراجعات'!$E$5:$E$1504,'سجل المراجعات'!$A$5:$A$1504,$A6,'سجل المراجعات'!$D$5:$D$1504,"رد بملاحظات")) -> 45721 | M6: =IF($A6="","",_xlfn.MAXIFS('سجل المراجعات'!$E$5:$E$1504,'سجل المراجعات'!$A$5:$A$1504,$A6,'سجل المراجعات'!$D$5:$D$1504,"قبول")) -> 45736 | N6: =IF($A6="","",COUNTIFS('سجل المراجعات'!$A$5:$A$1504,$A6,'سجل المراجعات'!$D$5:$D$1504,"تسليم")) -> 2 | O6: =IF($A6="","",IF(M6>0,"تم القبول",IF(F6="معلق","معلق",IF(AND(L6>0,L6>=K6),"مُعاد بملاحظات",IF(K6>0,"في انتظار القبول",IF(AND(ISNUMBER(E6),E6<تاريخ_الاحتساب),"متأخر",IF(F6="","لم يبدأ",F6))))))) -> تم القبول | P6: =IF($A6="","",SUMIFS('سجل المراجعات'!$L$5:$L$1504,'سجل المراجعات'!$A$5:$A$1504,$A6)) -> 23 | Q6: =IF($A6="","",SUMIFS('سجل المراجعات'!$M$5:$M$1504,'سجل المراجعات'!$A$5:$A$1504,$A6)) -> 7 | R6: =IF(OR($A6="",NOT(ISNUMBER(E6))),"",MAX(0,NETWORKDAYS.INTL(E6,IF(J6>0,J6,تاريخ_الاحتساب),رمز_العطلة,أيام_الأجازات)-1))
A7: D-003 | B7: 2 | C7: =IF($A7="","",IFERROR(INDEX(بند_الاسم,MATCH($B7,قائمة_البنود,0)),"⚠ بند غير موجود")) -> تحليل المتطلبات | D7: وثيقة متطلبات - الدفعة 1 | H7: =IF($A7="","",IFERROR(INDEX(بند_سعر_الوحدة,MATCH($B7,قائمة_البنود,0)),0)) -> 250000 | I7: =IF($A7="","",H7*(1+نسبة_الضريبة)) -> 287500 | J7: =IF($A7="","",_xlfn.MINIFS('سجل المراجعات'!$E$5:$E$1504,'سجل المراجعات'!$A$5:$A$1504,$A7,'سجل المراجعات'!$D$5:$D$1504,"تسليم")) -> 46082 | K7: =IF($A7="","",_xlfn.MAXIFS('سجل المراجعات'!$E$5:$E$1504,'سجل المراجعات'!$A$5:$A$1504,$A7,'سجل المراجعات'!$D$5:$D$1504,"تسليم")) -> 46082 | L7: =IF($A7="","",_xlfn.MAXIFS('سجل المراجعات'!$E$5:$E$1504,'سجل المراجعات'!$A$5:$A$1504,$A7,'سجل المراجعات'!$D$5:$D$1504,"رد بملاحظات")) -> 46127 | M7: =IF($A7="","",_xlfn.MAXIFS('سجل المراجعات'!$E$5:$E$1504,'سجل المراجعات'!$A$5:$A$1504,$A7,'سجل المراجعات'!$D$5:$D$1504,"قبول")) -> 0 | N7: =IF($A7="","",COUNTIFS('سجل المراجعات'!$A$5:$A$1504,$A7,'سجل المراجعات'!$D$5:$D$1504,"تسليم")) -> 1 | O7: =IF($A7="","",IF(M7>0,"تم القبول",IF(F7="معلق","معلق",IF(AND(L7>0,L7>=K7),"مُعاد بملاحظات",IF(K7>0,"في انتظار القبول",IF(AND(ISNUMBER(E7),E7<تاريخ_الاحتساب),"متأخر",IF(F7="","لم يبدأ",F7))))))) -> مُعاد بملاحظات | P7: =IF($A7="","",SUMIFS('سجل المراجعات'!$L$5:$L$1504,'سجل المراجعات'!$A$5:$A$1504,$A7)) -> 31 | Q7: =IF($A7="","",SUMIFS('سجل المراجعات'!$M$5:$M$1504,'سجل المراجعات'!$A$5:$A$1504,$A7)) -> 21 | R7: =IF(OR($A7="",NOT(ISNUMBER(E7))),"",MAX(0,NETWORKDAYS.INTL(E7,IF(J7>0,J7,تاريخ_الاحتساب),رمز_العطلة,أيام_الأجازات)-1))
A8: D-004 | B8: 2 | C8: =IF($A8="","",IFERROR(INDEX(بند_الاسم,MATCH($B8,قائمة_البنود,0)),"⚠ بند غير موجود")) -> تحليل المتطلبات | D8: وثيقة متطلبات - الدفعة 2 | H8: =IF($A8="","",IFERROR(INDEX(بند_سعر_الوحدة,MATCH($B8,قائمة_البنود,0)),0)) -> 250000 | I8: =IF($A8="","",H8*(1+نسبة_الضريبة)) -> 287500 | J8: =IF($A8="","",_xlfn.MINIFS('سجل المراجعات'!$E$5:$E$1504,'سجل المراجعات'!$A$5:$A$1504,$A8,'سجل المراجعات'!$D$5:$D$1504,"تسليم")) -> 46054 | K8: =IF($A8="","",_xlfn.MAXIFS('سجل المراجعات'!$E$5:$E$1504,'سجل المراجعات'!$A$5:$A$1504,$A8,'سجل المراجعات'!$D$5:$D$1504,"تسليم")) -> 46152 | L8: =IF($A8="","",_xlfn.MAXIFS('سجل المراجعات'!$E$5:$E$1504,'سجل المراجعات'!$A$5:$A$1504,$A8,'سجل المراجعات'!$D$5:$D$1504,"رد بملاحظات")) -> 0 | M8: =IF($A8="","",_xlfn.MAXIFS('سجل المراجعات'!$E$5:$E$1504,'سجل المراجعات'!$A$5:$A$1504,$A8,'سجل المراجعات'!$D$5:$D$1504,"قبول")) -> 0 | N8: =IF($A8="","",COUNTIFS('سجل المراجعات'!$A$5:$A$1504,$A8,'سجل المراجعات'!$D$5:$D$1504,"تسليم")) -> 2 | O8: =IF($A8="","",IF(M8>0,"تم القبول",IF(F8="معلق","معلق",IF(AND(L8>0,L8>=K8),"مُعاد بملاحظات",IF(K8>0,"في انتظار القبول",IF(AND(ISNUMBER(E8),E8<تاريخ_الاحتساب),"متأخر",IF(F8="","لم يبدأ",F8))))))) -> في انتظار القبول | P8: =IF($A8="","",SUMIFS('سجل المراجعات'!$L$5:$L$1504,'سجل المراجعات'!$A$5:$A$1504,$A8)) -> 101 | Q8: =IF($A8="","",SUMIFS('سجل المراجعات'!$M$5:$M$1504,'سجل المراجعات'!$A$5:$A$1504,$A8)) -> 81 | R8: =IF(OR($A8="",NOT(ISNUMBER(E8))),"",MAX(0,NETWORKDAYS.INTL(E8,IF(J8>0,J8,تاريخ_الاحتساب),رمز_العطلة,أيام_الأجازات)-1)) | S8: مثال: تسليم بدون رد ثم إعادة تسليم
A9: D-005 | B9: 2 | C9: =IF($A9="","",IFERROR(INDEX(بند_الاسم,MATCH($B9,قائمة_البنود,0)),"⚠ بند غير موجود")) -> تحليل المتطلبات | D9: وثيقة متطلبات - الدفعة 3 | E9: 46173 | F9: جاري العمل | G9: 18 | H9: =IF($A9="","",IFERROR(INDEX(بند_سعر_الوحدة,MATCH($B9,قائمة_البنود,0)),0)) -> 250000 | I9: =IF($A9="","",H9*(1+نسبة_الضريبة)) -> 287500 | J9: =IF($A9="","",_xlfn.MINIFS('سجل المراجعات'!$E$5:$E$1504,'سجل المراجعات'!$A$5:$A$1504,$A9,'سجل المراجعات'!$D$5:$D$1504,"تسليم")) -> 0 | K9: =IF($A9="","",_xlfn.MAXIFS('سجل المراجعات'!$E$5:$E$1504,'سجل المراجعات'!$A$5:$A$1504,$A9,'سجل المراجعات'!$D$5:$D$1504,"تسليم")) -> 0 | L9: =IF($A9="","",_xlfn.MAXIFS('سجل المراجعات'!$E$5:$E$1504,'سجل المراجعات'!$A$5:$A$1504,$A9,'سجل المراجعات'!$D$5:$D$1504,"رد بملاحظات")) -> 0 | M9: =IF($A9="","",_xlfn.MAXIFS('سجل المراجعات'!$E$5:$E$1504,'سجل المراجعات'!$A$5:$A$1504,$A9,'سجل المراجعات'!$D$5:$D$1504,"قبول")) -> 0 | N9: =IF($A9="","",COUNTIFS('سجل المراجعات'!$A$5:$A$1504,$A9,'سجل المراجعات'!$D$5:$D$1504,"تسليم")) -> 0 | O9: =IF($A9="","",IF(M9>0,"تم القبول",IF(F9="معلق","معلق",IF(AND(L9>0,L9>=K9),"مُعاد بملاحظات",IF(K9>0,"في انتظار القبول",IF(AND(ISNUMBER(E9),E9<تاريخ_الاحتساب),"متأخر",IF(F9="","لم يبدأ",F9))))))) -> متأخر | P9: =IF($A9="","",SUMIFS('سجل المراجعات'!$L$5:$L$1504,'سجل المراجعات'!$A$5:$A$1504,$A9)) -> 0 | Q9: =IF($A9="","",SUMIFS('سجل المراجعات'!$M$5:$M$1504,'سجل المراجعات'!$A$5:$A$1504,$A9)) -> 0 | R9: =IF(OR($A9="",NOT(ISNUMBER(E9))),"",MAX(0,NETWORKDAYS.INTL(E9,IF(J9>0,J9,تاريخ_الاحتساب),رمز_العطلة,أيام_الأجازات)-1)) -> 22
A10: D-006 | B10: 2 | C10: =IF($A10="","",IFERROR(INDEX(بند_الاسم,MATCH($B10,قائمة_البنود,0)),"⚠ بند غير موجود")) -> تحليل المتطلبات | D10: وثيقة متطلبات - الدفعة 4 | E10: 46295 | F10: لم يبدأ | H10: =IF($A10="","",IFERROR(INDEX(بند_سعر_الوحدة,MATCH($B10,قائمة_البنود,0)),0)) -> 250000 | I10: =IF($A10="","",H10*(1+نسبة_الضريبة)) -> 287500 | J10: =IF($A10="","",_xlfn.MINIFS('سجل المراجعات'!$E$5:$E$1504,'سجل المراجعات'!$A$5:$A$1504,$A10,'سجل المراجعات'!$D$5:$D$1504,"تسليم")) -> 0 | K10: =IF($A10="","",_xlfn.MAXIFS('سجل المراجعات'!$E$5:$E$1504,'سجل المراجعات'!$A$5:$A$1504,$A10,'سجل المراجعات'!$D$5:$D$1504,"تسليم")) -> 0 | L10: =IF($A10="","",_xlfn.MAXIFS('سجل المراجعات'!$E$5:$E$1504,'سجل المراجعات'!$A$5:$A$1504,$A10,'سجل المراجعات'!$D$5:$D$1504,"رد بملاحظات")) -> 0 | M10: =IF($A10="","",_xlfn.MAXIFS('سجل المراجعات'!$E$5:$E$1504,'سجل المراجعات'!$A$5:$A$1504,$A10,'سجل المراجعات'!$D$5:$D$1504,"قبول")) -> 0 | N10: =IF($A10="","",COUNTIFS('سجل المراجعات'!$A$5:$A$1504,$A10,'سجل المراجعات'!$D$5:$D$1504,"تسليم")) -> 0 | O10: =IF($A10="","",IF(M10>0,"تم القبول",IF(F10="معلق","معلق",IF(AND(L10>0,L10>=K10),"مُعاد بملاحظات",IF(K10>0,"في انتظار القبول",IF(AND(ISNUMBER(E10),E10<تاريخ_الاحتساب),"متأخر",IF(F10="","لم يبدأ",F10))))))) -> لم يبدأ | P10: =IF($A10="","",SUMIFS('سجل المراجعات'!$L$5:$L$1504,'سجل المراجعات'!$A$5:$A$1504,$A10)) -> 0 | Q10: =IF($A10="","",SUMIFS('سجل المراجعات'!$M$5:$M$1504,'سجل المراجعات'!$A$5:$A$1504,$A10)) -> 0 | R10: =IF(OR($A10="",NOT(ISNUMBER(E10))),"",MAX(0,NETWORKDAYS.INTL(E10,IF(J10>0,J10,تاريخ_الاحتساب),رمز_العطلة,أيام_الأجازات)-1)) -> 0
A11: D-007 | B11: 3.أ | C11: =IF($A11="","",IFERROR(INDEX(بند_الاسم,MATCH($B11,قائمة_البنود,0)),"⚠ بند غير موجود")) -> تطوير الخدمات | D11: تقرير تطوير الخدمات 1 | H11: =IF($A11="","",IFERROR(INDEX(بند_سعر_الوحدة,MATCH($B11,قائمة_البنود,0)),0)) -> 900000 | I11: =IF($A11="","",H11*(1+نسبة_الضريبة)) -> 1035000 | J11: =IF($A11="","",_xlfn.MINIFS('سجل المراجعات'!$E$5:$E$1504,'سجل المراجعات'!$A$5:$A$1504,$A11,'سجل المراجعات'!$D$5:$D$1504,"تسليم")) -> 46174 | K11: =IF($A11="","",_xlfn.MAXIFS('سجل المراجعات'!$E$5:$E$1504,'سجل المراجعات'!$A$5:$A$1504,$A11,'سجل المراجعات'!$D$5:$D$1504,"تسليم")) -> 46174 | L11: =IF($A11="","",_xlfn.MAXIFS('سجل المراجعات'!$E$5:$E$1504,'سجل المراجعات'!$A$5:$A$1504,$A11,'سجل المراجعات'!$D$5:$D$1504,"رد بملاحظات")) -> 0 | M11: =IF($A11="","",_xlfn.MAXIFS('سجل المراجعات'!$E$5:$E$1504,'سجل المراجعات'!$A$5:$A$1504,$A11,'سجل المراجعات'!$D$5:$D$1504,"قبول")) -> 0 | N11: =IF($A11="","",COUNTIFS('سجل المراجعات'!$A$5:$A$1504,$A11,'سجل المراجعات'!$D$5:$D$1504,"تسليم")) -> 1 | O11: =IF($A11="","",IF(M11>0,"تم القبول",IF(F11="معلق","معلق",IF(AND(L11>0,L11>=K11),"مُعاد بملاحظات",IF(K11>0,"في انتظار القبول",IF(AND(ISNUMBER(E11),E11<تاريخ_الاحتساب),"متأخر",IF(F11="","لم يبدأ",F11))))))) -> في انتظار القبول | P11: =IF($A11="","",SUMIFS('سجل المراجعات'!$L$5:$L$1504,'سجل المراجعات'!$A$5:$A$1504,$A11)) -> 21 | Q11: =IF($A11="","",SUMIFS('سجل المراجعات'!$M$5:$M$1504,'سجل المراجعات'!$A$5:$A$1504,$A11)) -> 11 | R11: =IF(OR($A11="",NOT(ISNUMBER(E11))),"",MAX(0,NETWORKDAYS.INTL(E11,IF(J11>0,J11,تاريخ_الاحتساب),رمز_العطلة,أيام_الأجازات)-1))
A12: D-008 | B12: 3.أ | C12: =IF($A12="","",IFERROR(INDEX(بند_الاسم,MATCH($B12,قائمة_البنود,0)),"⚠ بند غير موجود")) -> تطوير الخدمات | D12: تقرير تطوير الخدمات 2 | F12: معلق | H12: =IF($A12="","",IFERROR(INDEX(بند_سعر_الوحدة,MATCH($B12,قائمة_البنود,0)),0)) -> 900000 | I12: =IF($A12="","",H12*(1+نسبة_الضريبة)) -> 1035000 | J12: =IF($A12="","",_xlfn.MINIFS('سجل المراجعات'!$E$5:$E$1504,'سجل المراجعات'!$A$5:$A$1504,$A12,'سجل المراجعات'!$D$5:$D$1504,"تسليم")) -> 0 | K12: =IF($A12="","",_xlfn.MAXIFS('سجل المراجعات'!$E$5:$E$1504,'سجل المراجعات'!$A$5:$A$1504,$A12,'سجل المراجعات'!$D$5:$D$1504,"تسليم")) -> 0 | L12: =IF($A12="","",_xlfn.MAXIFS('سجل المراجعات'!$E$5:$E$1504,'سجل المراجعات'!$A$5:$A$1504,$A12,'سجل المراجعات'!$D$5:$D$1504,"رد بملاحظات")) -> 0 | M12: =IF($A12="","",_xlfn.MAXIFS('سجل المراجعات'!$E$5:$E$1504,'سجل المراجعات'!$A$5:$A$1504,$A12,'سجل المراجعات'!$D$5:$D$1504,"قبول")) -> 0 | N12: =IF($A12="","",COUNTIFS('سجل المراجعات'!$A$5:$A$1504,$A12,'سجل المراجعات'!$D$5:$D$1504,"تسليم")) -> 0 | O12: =IF($A12="","",IF(M12>0,"تم القبول",IF(F12="معلق","معلق",IF(AND(L12>0,L12>=K12),"مُعاد بملاحظات",IF(K12>0,"في انتظار القبول",IF(AND(ISNUMBER(E12),E12<تاريخ_الاحتساب),"متأخر",IF(F12="","لم يبدأ",F12))))))) -> معلق | P12: =IF($A12="","",SUMIFS('سجل المراجعات'!$L$5:$L$1504,'سجل المراجعات'!$A$5:$A$1504,$A12)) -> 0 | Q12: =IF($A12="","",SUMIFS('سجل المراجعات'!$M$5:$M$1504,'سجل المراجعات'!$A$5:$A$1504,$A12)) -> 0 | R12: =IF(OR($A12="",NOT(ISNUMBER(E12))),"",MAX(0,NETWORKDAYS.INTL(E12,IF(J12>0,J12,تاريخ_الاحتساب),رمز_العطلة,أيام_الأجازات)-1)) | S12: مثال: بند معلق بقرار من العميل
A13: D-009 | B13: 3.أ | C13: =IF($A13="","",IFERROR(INDEX(بند_الاسم,MATCH($B13,قائمة_البنود,0)),"⚠ بند غير موجود")) -> تطوير الخدمات | D13: تقرير تطوير الخدمات 3 | F13: جاري العمل | H13: =IF($A13="","",IFERROR(INDEX(بند_سعر_الوحدة,MATCH($B13,قائمة_البنود,0)),0)) -> 900000 | I13: =IF($A13="","",H13*(1+نسبة_الضريبة)) -> 1035000 | J13: =IF($A13="","",_xlfn.MINIFS('سجل المراجعات'!$E$5:$E$1504,'سجل المراجعات'!$A$5:$A$1504,$A13,'سجل المراجعات'!$D$5:$D$1504,"تسليم")) -> 0 | K13: =IF($A13="","",_xlfn.MAXIFS('سجل المراجعات'!$E$5:$E$1504,'سجل المراجعات'!$A$5:$A$1504,$A13,'سجل المراجعات'!$D$5:$D$1504,"تسليم")) -> 0 | L13: =IF($A13="","",_xlfn.MAXIFS('سجل المراجعات'!$E$5:$E$1504,'سجل المراجعات'!$A$5:$A$1504,$A13,'سجل المراجعات'!$D$5:$D$1504,"رد بملاحظات")) -> 0 | M13: =IF($A13="","",_xlfn.MAXIFS('سجل المراجعات'!$E$5:$E$1504,'سجل المراجعات'!$A$5:$A$1504,$A13,'سجل المراجعات'!$D$5:$D$1504,"قبول")) -> 0 | N13: =IF($A13="","",COUNTIFS('سجل المراجعات'!$A$5:$A$1504,$A13,'سجل المراجعات'!$D$5:$D$1504,"تسليم")) -> 0 | O13: =IF($A13="","",IF(M13>0,"تم القبول",IF(F13="معلق","معلق",IF(AND(L13>0,L13>=K13),"مُعاد بملاحظات",IF(K13>0,"في انتظار القبول",IF(AND(ISNUMBER(E13),E13<تاريخ_الاحتساب),"متأخر",IF(F13="","لم يبدأ",F13))))))) -> جاري العمل | P13: =IF($A13="","",SUMIFS('سجل المراجعات'!$L$5:$L$1504,'سجل المراجعات'!$A$5:$A$1504,$A13)) -> 0 | Q13: =IF($A13="","",SUMIFS('سجل المراجعات'!$M$5:$M$1504,'سجل المراجعات'!$A$5:$A$1504,$A13)) -> 0 | R13: =IF(OR($A13="",NOT(ISNUMBER(E13))),"",MAX(0,NETWORKDAYS.INTL(E13,IF(J13>0,J13,تاريخ_الاحتساب),رمز_العطلة,أيام_الأجازات)-1))
C14: =IF($A14="","",IFERROR(INDEX(بند_الاسم,MATCH($B14,قائمة_البنود,0)),"⚠ بند غير موجود")) | H14: =IF($A14="","",IFERROR(INDEX(بند_سعر_الوحدة,MATCH($B14,قائمة_البنود,0)),0)) | I14: =IF($A14="","",H14*(1+نسبة_الضريبة)) | J14: =IF($A14="","",_xlfn.MINIFS('سجل المراجعات'!$E$5:$E$1504,'سجل المراجعات'!$A$5:$A$1504,$A14,'سجل المراجعات'!$D$5:$D$1504,"تسليم")) | K14: =IF($A14="","",_xlfn.MAXIFS('سجل المراجعات'!$E$5:$E$1504,'سجل المراجعات'!$A$5:$A$1504,$A14,'سجل المراجعات'!$D$5:$D$1504,"تسليم")) | L14: =IF($A14="","",_xlfn.MAXIFS('سجل المراجعات'!$E$5:$E$1504,'سجل المراجعات'!$A$5:$A$1504,$A14,'سجل المراجعات'!$D$5:$D$1504,"رد بملاحظات")) | M14: =IF($A14="","",_xlfn.MAXIFS('سجل المراجعات'!$E$5:$E$1504,'سجل المراجعات'!$A$5:$A$1504,$A14,'سجل المراجعات'!$D$5:$D$1504,"قبول")) | N14: =IF($A14="","",COUNTIFS('سجل المراجعات'!$A$5:$A$1504,$A14,'سجل المراجعات'!$D$5:$D$1504,"تسليم")) | O14: =IF($A14="","",IF(M14>0,"تم القبول",IF(F14="معلق","معلق",IF(AND(L14>0,L14>=K14),"مُعاد بملاحظات",IF(K14>0,"في انتظار القبول",IF(AND(ISNUMBER(E14),E14<تاريخ_الاحتساب),"متأخر",IF(F14="","لم يبدأ",F14))))))) | P14: =IF($A14="","",SUMIFS('سجل المراجعات'!$L$5:$L$1504,'سجل المراجعات'!$A$5:$A$1504,$A14)) | Q14: =IF($A14="","",SUMIFS('سجل المراجعات'!$M$5:$M$1504,'سجل المراجعات'!$A$5:$A$1504,$A14)) | R14: =IF(OR($A14="",NOT(ISNUMBER(E14))),"",MAX(0,NETWORKDAYS.INTL(E14,IF(J14>0,J14,تاريخ_الاحتساب),رمز_العطلة,أيام_الأجازات)-1))
C15: =IF($A15="","",IFERROR(INDEX(بند_الاسم,MATCH($B15,قائمة_البنود,0)),"⚠ بند غير موجود")) | H15: =IF($A15="","",IFERROR(INDEX(بند_سعر_الوحدة,MATCH($B15,قائمة_البنود,0)),0)) | I15: =IF($A15="","",H15*(1+نسبة_الضريبة)) | J15: =IF($A15="","",_xlfn.MINIFS('سجل المراجعات'!$E$5:$E$1504,'سجل المراجعات'!$A$5:$A$1504,$A15,'سجل المراجعات'!$D$5:$D$1504,"تسليم")) | K15: =IF($A15="","",_xlfn.MAXIFS('سجل المراجعات'!$E$5:$E$1504,'سجل المراجعات'!$A$5:$A$1504,$A15,'سجل المراجعات'!$D$5:$D$1504,"تسليم")) | L15: =IF($A15="","",_xlfn.MAXIFS('سجل المراجعات'!$E$5:$E$1504,'سجل المراجعات'!$A$5:$A$1504,$A15,'سجل المراجعات'!$D$5:$D$1504,"رد بملاحظات")) | M15: =IF($A15="","",_xlfn.MAXIFS('سجل المراجعات'!$E$5:$E$1504,'سجل المراجعات'!$A$5:$A$1504,$A15,'سجل المراجعات'!$D$5:$D$1504,"قبول")) | N15: =IF($A15="","",COUNTIFS('سجل المراجعات'!$A$5:$A$1504,$A15,'سجل المراجعات'!$D$5:$D$1504,"تسليم")) | O15: =IF($A15="","",IF(M15>0,"تم القبول",IF(F15="معلق","معلق",IF(AND(L15>0,L15>=K15),"مُعاد بملاحظات",IF(K15>0,"في انتظار القبول",IF(AND(ISNUMBER(E15),E15<تاريخ_الاحتساب),"متأخر",IF(F15="","لم يبدأ",F15))))))) | P15: =IF($A15="","",SUMIFS('سجل المراجعات'!$L$5:$L$1504,'سجل المراجعات'!$A$5:$A$1504,$A15)) | Q15: =IF($A15="","",SUMIFS('سجل المراجعات'!$M$5:$M$1504,'سجل المراجعات'!$A$5:$A$1504,$A15)) | R15: =IF(OR($A15="",NOT(ISNUMBER(E15))),"",MAX(0,NETWORKDAYS.INTL(E15,IF(J15>0,J15,تاريخ_الاحتساب),رمز_العطلة,أيام_الأجازات)-1))
C16: =IF($A16="","",IFERROR(INDEX(بند_الاسم,MATCH($B16,قائمة_البنود,0)),"⚠ بند غير موجود")) | H16: =IF($A16="","",IFERROR(INDEX(بند_سعر_الوحدة,MATCH($B16,قائمة_البنود,0)),0)) | I16: =IF($A16="","",H16*(1+نسبة_الضريبة)) | J16: =IF($A16="","",_xlfn.MINIFS('سجل المراجعات'!$E$5:$E$1504,'سجل المراجعات'!$A$5:$A$1504,$A16,'سجل المراجعات'!$D$5:$D$1504,"تسليم")) | K16: =IF($A16="","",_xlfn.MAXIFS('سجل المراجعات'!$E$5:$E$1504,'سجل المراجعات'!$A$5:$A$1504,$A16,'سجل المراجعات'!$D$5:$D$1504,"تسليم")) | L16: =IF($A16="","",_xlfn.MAXIFS('سجل المراجعات'!$E$5:$E$1504,'سجل المراجعات'!$A$5:$A$1504,$A16,'سجل المراجعات'!$D$5:$D$1504,"رد بملاحظات")) | M16: =IF($A16="","",_xlfn.MAXIFS('سجل المراجعات'!$E$5:$E$1504,'سجل المراجعات'!$A$5:$A$1504,$A16,'سجل المراجعات'!$D$5:$D$1504,"قبول")) | N16: =IF($A16="","",COUNTIFS('سجل المراجعات'!$A$5:$A$1504,$A16,'سجل المراجعات'!$D$5:$D$1504,"تسليم")) | O16: =IF($A16="","",IF(M16>0,"تم القبول",IF(F16="معلق","معلق",IF(AND(L16>0,L16>=K16),"مُعاد بملاحظات",IF(K16>0,"في انتظار القبول",IF(AND(ISNUMBER(E16),E16<تاريخ_الاحتساب),"متأخر",IF(F16="","لم يبدأ",F16))))))) | P16: =IF($A16="","",SUMIFS('سجل المراجعات'!$L$5:$L$1504,'سجل المراجعات'!$A$5:$A$1504,$A16)) | Q16: =IF($A16="","",SUMIFS('سجل المراجعات'!$M$5:$M$1504,'سجل المراجعات'!$A$5:$A$1504,$A16)) | R16: =IF(OR($A16="",NOT(ISNUMBER(E16))),"",MAX(0,NETWORKDAYS.INTL(E16,IF(J16>0,J16,تاريخ_الاحتساب),رمز_العطلة,أيام_الأجازات)-1))
C17: =IF($A17="","",IFERROR(INDEX(بند_الاسم,MATCH($B17,قائمة_البنود,0)),"⚠ بند غير موجود")) | H17: =IF($A17="","",IFERROR(INDEX(بند_سعر_الوحدة,MATCH($B17,قائمة_البنود,0)),0)) | I17: =IF($A17="","",H17*(1+نسبة_الضريبة)) | J17: =IF($A17="","",_xlfn.MINIFS('سجل المراجعات'!$E$5:$E$1504,'سجل المراجعات'!$A$5:$A$1504,$A17,'سجل المراجعات'!$D$5:$D$1504,"تسليم")) | K17: =IF($A17="","",_xlfn.MAXIFS('سجل المراجعات'!$E$5:$E$1504,'سجل المراجعات'!$A$5:$A$1504,$A17,'سجل المراجعات'!$D$5:$D$1504,"تسليم")) | L17: =IF($A17="","",_xlfn.MAXIFS('سجل المراجعات'!$E$5:$E$1504,'سجل المراجعات'!$A$5:$A$1504,$A17,'سجل المراجعات'!$D$5:$D$1504,"رد بملاحظات")) | M17: =IF($A17="","",_xlfn.MAXIFS('سجل المراجعات'!$E$5:$E$1504,'سجل المراجعات'!$A$5:$A$1504,$A17,'سجل المراجعات'!$D$5:$D$1504,"قبول")) | N17: =IF($A17="","",COUNTIFS('سجل المراجعات'!$A$5:$A$1504,$A17,'سجل المراجعات'!$D$5:$D$1504,"تسليم")) | O17: =IF($A17="","",IF(M17>0,"تم القبول",IF(F17="معلق","معلق",IF(AND(L17>0,L17>=K17),"مُعاد بملاحظات",IF(K17>0,"في انتظار القبول",IF(AND(ISNUMBER(E17),E17<تاريخ_الاحتساب),"متأخر",IF(F17="","لم يبدأ",F17))))))) | P17: =IF($A17="","",SUMIFS('سجل المراجعات'!$L$5:$L$1504,'سجل المراجعات'!$A$5:$A$1504,$A17)) | Q17: =IF($A17="","",SUMIFS('سجل المراجعات'!$M$5:$M$1504,'سجل المراجعات'!$A$5:$A$1504,$A17)) | R17: =IF(OR($A17="",NOT(ISNUMBER(E17))),"",MAX(0,NETWORKDAYS.INTL(E17,IF(J17>0,J17,تاريخ_الاحتساب),رمز_العطلة,أيام_الأجازات)-1))
C18: =IF($A18="","",IFERROR(INDEX(بند_الاسم,MATCH($B18,قائمة_البنود,0)),"⚠ بند غير موجود")) | H18: =IF($A18="","",IFERROR(INDEX(بند_سعر_الوحدة,MATCH($B18,قائمة_البنود,0)),0)) | I18: =IF($A18="","",H18*(1+نسبة_الضريبة)) | J18: =IF($A18="","",_xlfn.MINIFS('سجل المراجعات'!$E$5:$E$1504,'سجل المراجعات'!$A$5:$A$1504,$A18,'سجل المراجعات'!$D$5:$D$1504,"تسليم")) | K18: =IF($A18="","",_xlfn.MAXIFS('سجل المراجعات'!$E$5:$E$1504,'سجل المراجعات'!$A$5:$A$1504,$A18,'سجل المراجعات'!$D$5:$D$1504,"تسليم")) | L18: =IF($A18="","",_xlfn.MAXIFS('سجل المراجعات'!$E$5:$E$1504,'سجل المراجعات'!$A$5:$A$1504,$A18,'سجل المراجعات'!$D$5:$D$1504,"رد بملاحظات")) | M18: =IF($A18="","",_xlfn.MAXIFS('سجل المراجعات'!$E$5:$E$1504,'سجل المراجعات'!$A$5:$A$1504,$A18,'سجل المراجعات'!$D$5:$D$1504,"قبول")) | N18: =IF($A18="","",COUNTIFS('سجل المراجعات'!$A$5:$A$1504,$A18,'سجل المراجعات'!$D$5:$D$1504,"تسليم")) | O18: =IF($A18="","",IF(M18>0,"تم القبول",IF(F18="معلق","معلق",IF(AND(L18>0,L18>=K18),"مُعاد بملاحظات",IF(K18>0,"في انتظار القبول",IF(AND(ISNUMBER(E18),E18<تاريخ_الاحتساب),"متأخر",IF(F18="","لم يبدأ",F18))))))) | P18: =IF($A18="","",SUMIFS('سجل المراجعات'!$L$5:$L$1504,'سجل المراجعات'!$A$5:$A$1504,$A18)) | Q18: =IF($A18="","",SUMIFS('سجل المراجعات'!$M$5:$M$1504,'سجل المراجعات'!$A$5:$A$1504,$A18)) | R18: =IF(OR($A18="",NOT(ISNUMBER(E18))),"",MAX(0,NETWORKDAYS.INTL(E18,IF(J18>0,J18,تاريخ_الاحتساب),رمز_العطلة,أيام_الأجازات)-1))
C19: =IF($A19="","",IFERROR(INDEX(بند_الاسم,MATCH($B19,قائمة_البنود,0)),"⚠ بند غير موجود")) | H19: =IF($A19="","",IFERROR(INDEX(بند_سعر_الوحدة,MATCH($B19,قائمة_البنود,0)),0)) | I19: =IF($A19="","",H19*(1+نسبة_الضريبة)) | J19: =IF($A19="","",_xlfn.MINIFS('سجل المراجعات'!$E$5:$E$1504,'سجل المراجعات'!$A$5:$A$1504,$A19,'سجل المراجعات'!$D$5:$D$1504,"تسليم")) | K19: =IF($A19="","",_xlfn.MAXIFS('سجل المراجعات'!$E$5:$E$1504,'سجل المراجعات'!$A$5:$A$1504,$A19,'سجل المراجعات'!$D$5:$D$1504,"تسليم")) | L19: =IF($A19="","",_xlfn.MAXIFS('سجل المراجعات'!$E$5:$E$1504,'سجل المراجعات'!$A$5:$A$1504,$A19,'سجل المراجعات'!$D$5:$D$1504,"رد بملاحظات")) | M19: =IF($A19="","",_xlfn.MAXIFS('سجل المراجعات'!$E$5:$E$1504,'سجل المراجعات'!$A$5:$A$1504,$A19,'سجل المراجعات'!$D$5:$D$1504,"قبول")) | N19: =IF($A19="","",COUNTIFS('سجل المراجعات'!$A$5:$A$1504,$A19,'سجل المراجعات'!$D$5:$D$1504,"تسليم")) | O19: =IF($A19="","",IF(M19>0,"تم القبول",IF(F19="معلق","معلق",IF(AND(L19>0,L19>=K19),"مُعاد بملاحظات",IF(K19>0,"في انتظار القبول",IF(AND(ISNUMBER(E19),E19<تاريخ_الاحتساب),"متأخر",IF(F19="","لم يبدأ",F19))))))) | P19: =IF($A19="","",SUMIFS('سجل المراجعات'!$L$5:$L$1504,'سجل المراجعات'!$A$5:$A$1504,$A19)) | Q19: =IF($A19="","",SUMIFS('سجل المراجعات'!$M$5:$M$1504,'سجل المراجعات'!$A$5:$A$1504,$A19)) | R19: =IF(OR($A19="",NOT(ISNUMBER(E19))),"",MAX(0,NETWORKDAYS.INTL(E19,IF(J19>0,J19,تاريخ_الاحتساب),رمز_العطلة,أيام_الأجازات)-1))
C20: =IF($A20="","",IFERROR(INDEX(بند_الاسم,MATCH($B20,قائمة_البنود,0)),"⚠ بند غير موجود")) | H20: =IF($A20="","",IFERROR(INDEX(بند_سعر_الوحدة,MATCH($B20,قائمة_البنود,0)),0)) | I20: =IF($A20="","",H20*(1+نسبة_الضريبة)) | J20: =IF($A20="","",_xlfn.MINIFS('سجل المراجعات'!$E$5:$E$1504,'سجل المراجعات'!$A$5:$A$1504,$A20,'سجل المراجعات'!$D$5:$D$1504,"تسليم")) | K20: =IF($A20="","",_xlfn.MAXIFS('سجل المراجعات'!$E$5:$E$1504,'سجل المراجعات'!$A$5:$A$1504,$A20,'سجل المراجعات'!$D$5:$D$1504,"تسليم")) | L20: =IF($A20="","",_xlfn.MAXIFS('سجل المراجعات'!$E$5:$E$1504,'سجل المراجعات'!$A$5:$A$1504,$A20,'سجل المراجعات'!$D$5:$D$1504,"رد بملاحظات")) | M20: =IF($A20="","",_xlfn.MAXIFS('سجل المراجعات'!$E$5:$E$1504,'سجل المراجعات'!$A$5:$A$1504,$A20,'سجل المراجعات'!$D$5:$D$1504,"قبول")) | N20: =IF($A20="","",COUNTIFS('سجل المراجعات'!$A$5:$A$1504,$A20,'سجل المراجعات'!$D$5:$D$1504,"تسليم")) | O20: =IF($A20="","",IF(M20>0,"تم القبول",IF(F20="معلق","معلق",IF(AND(L20>0,L20>=K20),"مُعاد بملاحظات",IF(K20>0,"في انتظار القبول",IF(AND(ISNUMBER(E20),E20<تاريخ_الاحتساب),"متأخر",IF(F20="","لم يبدأ",F20))))))) | P20: =IF($A20="","",SUMIFS('سجل المراجعات'!$L$5:$L$1504,'سجل المراجعات'!$A$5:$A$1504,$A20)) | Q20: =IF($A20="","",SUMIFS('سجل المراجعات'!$M$5:$M$1504,'سجل المراجعات'!$A$5:$A$1504,$A20)) | R20: =IF(OR($A20="",NOT(ISNUMBER(E20))),"",MAX(0,NETWORKDAYS.INTL(E20,IF(J20>0,J20,تاريخ_الاحتساب),رمز_العطلة,أيام_الأجازات)-1))
C21: =IF($A21="","",IFERROR(INDEX(بند_الاسم,MATCH($B21,قائمة_البنود,0)),"⚠ بند غير موجود")) | H21: =IF($A21="","",IFERROR(INDEX(بند_سعر_الوحدة,MATCH($B21,قائمة_البنود,0)),0)) | I21: =IF($A21="","",H21*(1+نسبة_الضريبة)) | J21: =IF($A21="","",_xlfn.MINIFS('سجل المراجعات'!$E$5:$E$1504,'سجل المراجعات'!$A$5:$A$1504,$A21,'سجل المراجعات'!$D$5:$D$1504,"تسليم")) | K21: =IF($A21="","",_xlfn.MAXIFS('سجل المراجعات'!$E$5:$E$1504,'سجل المراجعات'!$A$5:$A$1504,$A21,'سجل المراجعات'!$D$5:$D$1504,"تسليم")) | L21: =IF($A21="","",_xlfn.MAXIFS('سجل المراجعات'!$E$5:$E$1504,'سجل المراجعات'!$A$5:$A$1504,$A21,'سجل المراجعات'!$D$5:$D$1504,"رد بملاحظات")) | M21: =IF($A21="","",_xlfn.MAXIFS('سجل المراجعات'!$E$5:$E$1504,'سجل المراجعات'!$A$5:$A$1504,$A21,'سجل المراجعات'!$D$5:$D$1504,"قبول")) | N21: =IF($A21="","",COUNTIFS('سجل المراجعات'!$A$5:$A$1504,$A21,'سجل المراجعات'!$D$5:$D$1504,"تسليم")) | O21: =IF($A21="","",IF(M21>0,"تم القبول",IF(F21="معلق","معلق",IF(AND(L21>0,L21>=K21),"مُعاد بملاحظات",IF(K21>0,"في انتظار القبول",IF(AND(ISNUMBER(E21),E21<تاريخ_الاحتساب),"متأخر",IF(F21="","لم يبدأ",F21))))))) | P21: =IF($A21="","",SUMIFS('سجل المراجعات'!$L$5:$L$1504,'سجل المراجعات'!$A$5:$A$1504,$A21)) | Q21: =IF($A21="","",SUMIFS('سجل المراجعات'!$M$5:$M$1504,'سجل المراجعات'!$A$5:$A$1504,$A21)) | R21: =IF(OR($A21="",NOT(ISNUMBER(E21))),"",MAX(0,NETWORKDAYS.INTL(E21,IF(J21>0,J21,تاريخ_الاحتساب),رمز_العطلة,أيام_الأجازات)-1))
C22: =IF($A22="","",IFERROR(INDEX(بند_الاسم,MATCH($B22,قائمة_البنود,0)),"⚠ بند غير موجود")) | H22: =IF($A22="","",IFERROR(INDEX(بند_سعر_الوحدة,MATCH($B22,قائمة_البنود,0)),0)) | I22: =IF($A22="","",H22*(1+نسبة_الضريبة)) | J22: =IF($A22="","",_xlfn.MINIFS('سجل المراجعات'!$E$5:$E$1504,'سجل المراجعات'!$A$5:$A$1504,$A22,'سجل المراجعات'!$D$5:$D$1504,"تسليم")) | K22: =IF($A22="","",_xlfn.MAXIFS('سجل المراجعات'!$E$5:$E$1504,'سجل المراجعات'!$A$5:$A$1504,$A22,'سجل المراجعات'!$D$5:$D$1504,"تسليم")) | L22: =IF($A22="","",_xlfn.MAXIFS('سجل المراجعات'!$E$5:$E$1504,'سجل المراجعات'!$A$5:$A$1504,$A22,'سجل المراجعات'!$D$5:$D$1504,"رد بملاحظات")) | M22: =IF($A22="","",_xlfn.MAXIFS('سجل المراجعات'!$E$5:$E$1504,'سجل المراجعات'!$A$5:$A$1504,$A22,'سجل المراجعات'!$D$5:$D$1504,"قبول")) | N22: =IF($A22="","",COUNTIFS('سجل المراجعات'!$A$5:$A$1504,$A22,'سجل المراجعات'!$D$5:$D$1504,"تسليم")) | O22: =IF($A22="","",IF(M22>0,"تم القبول",IF(F22="معلق","معلق",IF(AND(L22>0,L22>=K22),"مُعاد بملاحظات",IF(K22>0,"في انتظار القبول",IF(AND(ISNUMBER(E22),E22<تاريخ_الاحتساب),"متأخر",IF(F22="","لم يبدأ",F22))))))) | P22: =IF($A22="","",SUMIFS('سجل المراجعات'!$L$5:$L$1504,'سجل المراجعات'!$A$5:$A$1504,$A22)) | Q22: =IF($A22="","",SUMIFS('سجل المراجعات'!$M$5:$M$1504,'سجل المراجعات'!$A$5:$A$1504,$A22)) | R22: =IF(OR($A22="",NOT(ISNUMBER(E22))),"",MAX(0,NETWORKDAYS.INTL(E22,IF(J22>0,J22,تاريخ_الاحتساب),رمز_العطلة,أيام_الأجازات)-1))
C23: =IF($A23="","",IFERROR(INDEX(بند_الاسم,MATCH($B23,قائمة_البنود,0)),"⚠ بند غير موجود")) | H23: =IF($A23="","",IFERROR(INDEX(بند_سعر_الوحدة,MATCH($B23,قائمة_البنود,0)),0)) | I23: =IF($A23="","",H23*(1+نسبة_الضريبة)) | J23: =IF($A23="","",_xlfn.MINIFS('سجل المراجعات'!$E$5:$E$1504,'سجل المراجعات'!$A$5:$A$1504,$A23,'سجل المراجعات'!$D$5:$D$1504,"تسليم")) | K23: =IF($A23="","",_xlfn.MAXIFS('سجل المراجعات'!$E$5:$E$1504,'سجل المراجعات'!$A$5:$A$1504,$A23,'سجل المراجعات'!$D$5:$D$1504,"تسليم")) | L23: =IF($A23="","",_xlfn.MAXIFS('سجل المراجعات'!$E$5:$E$1504,'سجل المراجعات'!$A$5:$A$1504,$A23,'سجل المراجعات'!$D$5:$D$1504,"رد بملاحظات")) | M23: =IF($A23="","",_xlfn.MAXIFS('سجل المراجعات'!$E$5:$E$1504,'سجل المراجعات'!$A$5:$A$1504,$A23,'سجل المراجعات'!$D$5:$D$1504,"قبول")) | N23: =IF($A23="","",COUNTIFS('سجل المراجعات'!$A$5:$A$1504,$A23,'سجل المراجعات'!$D$5:$D$1504,"تسليم")) | O23: =IF($A23="","",IF(M23>0,"تم القبول",IF(F23="معلق","معلق",IF(AND(L23>0,L23>=K23),"مُعاد بملاحظات",IF(K23>0,"في انتظار القبول",IF(AND(ISNUMBER(E23),E23<تاريخ_الاحتساب),"متأخر",IF(F23="","لم يبدأ",F23))))))) | P23: =IF($A23="","",SUMIFS('سجل المراجعات'!$L$5:$L$1504,'سجل المراجعات'!$A$5:$A$1504,$A23)) | Q23: =IF($A23="","",SUMIFS('سجل المراجعات'!$M$5:$M$1504,'سجل المراجعات'!$A$5:$A$1504,$A23)) | R23: =IF(OR($A23="",NOT(ISNUMBER(E23))),"",MAX(0,NETWORKDAYS.INTL(E23,IF(J23>0,J23,تاريخ_الاحتساب),رمز_العطلة,أيام_الأجازات)-1))
C24: =IF($A24="","",IFERROR(INDEX(بند_الاسم,MATCH($B24,قائمة_البنود,0)),"⚠ بند غير موجود")) | H24: =IF($A24="","",IFERROR(INDEX(بند_سعر_الوحدة,MATCH($B24,قائمة_البنود,0)),0)) | I24: =IF($A24="","",H24*(1+نسبة_الضريبة)) | J24: =IF($A24="","",_xlfn.MINIFS('سجل المراجعات'!$E$5:$E$1504,'سجل المراجعات'!$A$5:$A$1504,$A24,'سجل المراجعات'!$D$5:$D$1504,"تسليم")) | K24: =IF($A24="","",_xlfn.MAXIFS('سجل المراجعات'!$E$5:$E$1504,'سجل المراجعات'!$A$5:$A$1504,$A24,'سجل المراجعات'!$D$5:$D$1504,"تسليم")) | L24: =IF($A24="","",_xlfn.MAXIFS('سجل المراجعات'!$E$5:$E$1504,'سجل المراجعات'!$A$5:$A$1504,$A24,'سجل المراجعات'!$D$5:$D$1504,"رد بملاحظات")) | M24: =IF($A24="","",_xlfn.MAXIFS('سجل المراجعات'!$E$5:$E$1504,'سجل المراجعات'!$A$5:$A$1504,$A24,'سجل المراجعات'!$D$5:$D$1504,"قبول")) | N24: =IF($A24="","",COUNTIFS('سجل المراجعات'!$A$5:$A$1504,$A24,'سجل المراجعات'!$D$5:$D$1504,"تسليم")) | O24: =IF($A24="","",IF(M24>0,"تم القبول",IF(F24="معلق","معلق",IF(AND(L24>0,L24>=K24),"مُعاد بملاحظات",IF(K24>0,"في انتظار القبول",IF(AND(ISNUMBER(E24),E24<تاريخ_الاحتساب),"متأخر",IF(F24="","لم يبدأ",F24))))))) | P24: =IF($A24="","",SUMIFS('سجل المراجعات'!$L$5:$L$1504,'سجل المراجعات'!$A$5:$A$1504,$A24)) | Q24: =IF($A24="","",SUMIFS('سجل المراجعات'!$M$5:$M$1504,'سجل المراجعات'!$A$5:$A$1504,$A24)) | R24: =IF(OR($A24="",NOT(ISNUMBER(E24))),"",MAX(0,NETWORKDAYS.INTL(E24,IF(J24>0,J24,تاريخ_الاحتساب),رمز_العطلة,أيام_الأجازات)-1))
C25: =IF($A25="","",IFERROR(INDEX(بند_الاسم,MATCH($B25,قائمة_البنود,0)),"⚠ بند غير موجود")) | H25: =IF($A25="","",IFERROR(INDEX(بند_سعر_الوحدة,MATCH($B25,قائمة_البنود,0)),0)) | I25: =IF($A25="","",H25*(1+نسبة_الضريبة)) | J25: =IF($A25="","",_xlfn.MINIFS('سجل المراجعات'!$E$5:$E$1504,'سجل المراجعات'!$A$5:$A$1504,$A25,'سجل المراجعات'!$D$5:$D$1504,"تسليم")) | K25: =IF($A25="","",_xlfn.MAXIFS('سجل المراجعات'!$E$5:$E$1504,'سجل المراجعات'!$A$5:$A$1504,$A25,'سجل المراجعات'!$D$5:$D$1504,"تسليم")) | L25: =IF($A25="","",_xlfn.MAXIFS('سجل المراجعات'!$E$5:$E$1504,'سجل المراجعات'!$A$5:$A$1504,$A25,'سجل المراجعات'!$D$5:$D$1504,"رد بملاحظات")) | M25: =IF($A25="","",_xlfn.MAXIFS('سجل المراجعات'!$E$5:$E$1504,'سجل المراجعات'!$A$5:$A$1504,$A25,'سجل المراجعات'!$D$5:$D$1504,"قبول")) | N25: =IF($A25="","",COUNTIFS('سجل المراجعات'!$A$5:$A$1504,$A25,'سجل المراجعات'!$D$5:$D$1504,"تسليم")) | O25: =IF($A25="","",IF(M25>0,"تم القبول",IF(F25="معلق","معلق",IF(AND(L25>0,L25>=K25),"مُعاد بملاحظات",IF(K25>0,"في انتظار القبول",IF(AND(ISNUMBER(E25),E25<تاريخ_الاحتساب),"متأخر",IF(F25="","لم يبدأ",F25))))))) | P25: =IF($A25="","",SUMIFS('سجل المراجعات'!$L$5:$L$1504,'سجل المراجعات'!$A$5:$A$1504,$A25)) | Q25: =IF($A25="","",SUMIFS('سجل المراجعات'!$M$5:$M$1504,'سجل المراجعات'!$A$5:$A$1504,$A25)) | R25: =IF(OR($A25="",NOT(ISNUMBER(E25))),"",MAX(0,NETWORKDAYS.INTL(E25,IF(J25>0,J25,تاريخ_الاحتساب),رمز_العطلة,أيام_الأجازات)-1))
... C404: =IF($A404="","",IFERROR(INDEX(بند_الاسم,MATCH($B404,قائمة_البنود,0)),"⚠ بند غير موجود")) | H404: =IF($A404="","",IFERROR(INDEX(بند_سعر_الوحدة,MATCH($B404,قائمة_البنود,0)),0)) | I404: =IF($A404="","",H404*(1+نسبة_الضريبة)) | J404: =IF($A404="","",_xlfn.MINIFS('سجل المراجعات'!$E$5:$E$1504,'سجل المراجعات'!$A$5:$A$1504,$A404,'سجل المراجعات'!$D$5:$D$1504,"تسليم")) | K404: =IF($A404="","",_xlfn.MAXIFS('سجل المراجعات'!$E$5:$E$1504,'سجل المراجعات'!$A$5:$A$1504,$A404,'سجل المراجعات'!$D$5:$D$1504,"تسليم")) | L404: =IF($A404="","",_xlfn.MAXIFS('سجل المراجعات'!$E$5:$E$1504,'سجل المراجعات'!$A$5:$A$1504,$A404,'سجل المراجعات'!$D$5:$D$1504,"رد بملاحظات")) | M404: =IF($A404="","",_xlfn.MAXIFS('سجل المراجعات'!$E$5:$E$1504,'سجل المراجعات'!$A$5:$A$1504,$A404,'سجل المراجعات'!$D$5:$D$1504,"قبول")) | N404: =IF($A404="","",COUNTIFS('سجل المراجعات'!$A$5:$A$1504,$A404,'سجل المراجعات'!$D$5:$D$1504,"تسليم")) | O404: =IF($A404="","",IF(M404>0,"تم القبول",IF(F404="معلق","معلق",IF(AND(L404>0,L404>=K404),"مُعاد بملاحظات",IF(K404>0,"في انتظار القبول",IF(AND(ISNUMBER(E404),E404<تاريخ_الاحتساب),"متأخر",IF(F404="","لم يبدأ",F404))))))) | P404: =IF($A404="","",SUMIFS('سجل المراجعات'!$L$5:$L$1504,'سجل المراجعات'!$A$5:$A$1504,$A404)) | Q404: =IF($A404="","",SUMIFS('سجل المراجعات'!$M$5:$M$1504,'سجل المراجعات'!$A$5:$A$1504,$A404)) | R404: =IF(OR($A404="",NOT(ISNUMBER(E404))),"",MAX(0,NETWORKDAYS.INTL(E404,IF(J404>0,J404,تاريخ_الاحتساب),رمز_العطلة,أيام_الأجازات)-1))

Sheet سجل المراجعات
A1: سجل المراجعات
A2: سجّل كل حركة في صف: تسليم / رد بملاحظات / قبول — الترتيب مش مهم
A4: رقم المخرج | B4: رقم البند | C4: وصف المخرج | D4: نوع الحركة | E4: التاريخ | F4: ملاحظات | G4: رقم الدورة | H4: أول رد/قبول بعده | I4: التسليم التالي | J4: نهاية الدورة | K4: حالة الدورة | L4: أيام المراجعة | M4: أيام التأخير | N4: تنبيه
A5: D-001 | B5: =IF($A5="","",IFERROR(INDEX(مخرج_البند,MATCH($A5,قائمة_المخرجات,0)),"")) -> 1 | C5: =IF($A5="","",IFERROR(INDEX(مخرج_الوصف,MATCH($A5,قائمة_المخرجات,0)),"")) -> وثيقة ميثاق المشروع | D5: تسليم | E5: 45698 | G5: =IF(OR($A5="",$D5<>"تسليم",NOT(ISNUMBER($E5))),"",COUNTIFS($A$5:$A$1504,$A5,$D$5:$D$1504,"تسليم",$E$5:$E$1504,"<"&$E5)+1) -> 1 | H5: =IF($G5="","",_xlfn.MINIFS($E$5:$E$1504,$A$5:$A$1504,$A5,$D$5:$D$1504,"<>تسليم",$E$5:$E$1504,">="&$E5)) -> 45705 | I5: =IF($G5="","",_xlfn.MINIFS($E$5:$E$1504,$A$5:$A$1504,$A5,$D$5:$D$1504,"تسليم",$E$5:$E$1504,">"&$E5)) -> 0 | J5: =IF($G5="","",IF(H5>0,IF(I5>0,MIN(H5,I5),H5),IF(I5>0,I5,تاريخ_الاحتساب))) -> 45705 | K5: =IF($G5="","",IF(AND(H5=0,I5=0),"جارية","مغلقة")) -> مغلقة | L5: =IF($G5="","",MAX(0,NETWORKDAYS.INTL($E5,J5,رمز_العطلة,أيام_الأجازات)-1)) -> 5 | M5: =IF($G5="","",MAX(0,L5-مهلة_المراجعة)) -> 0 | N5: =IF($A5="",IF(OR($D5<>"",$E5<>""),"رقم المخرج ناقص",""),IF(ISNA(MATCH($A5,قائمة_المخرجات,0)),"رقم مخرج غير موجود",IF($D5="","نوع الحركة ناقص",IF(NOT(ISNUMBER($E5)),"التاريخ ناقص",IF($E5>تاريخ_الاحتساب,"تاريخ بعد تاريخ الاحتساب",IF(AND($D5<>"تسليم",COUNTIFS($A$5:$A$1504,$A5,$D$5:$D$1504,"تسليم",$E$5:$E$1504,"<="&$E5)=0),"لا يوجد تسليم قبل الحركة دي",""))))))
A6: D-001 | B6: =IF($A6="","",IFERROR(INDEX(مخرج_البند,MATCH($A6,قائمة_المخرجات,0)),"")) -> 1 | C6: =IF($A6="","",IFERROR(INDEX(مخرج_الوصف,MATCH($A6,قائمة_المخرجات,0)),"")) -> وثيقة ميثاق المشروع | D6: قبول | E6: 45705 | G6: =IF(OR($A6="",$D6<>"تسليم",NOT(ISNUMBER($E6))),"",COUNTIFS($A$5:$A$1504,$A6,$D$5:$D$1504,"تسليم",$E$5:$E$1504,"<"&$E6)+1) | H6: =IF($G6="","",_xlfn.MINIFS($E$5:$E$1504,$A$5:$A$1504,$A6,$D$5:$D$1504,"<>تسليم",$E$5:$E$1504,">="&$E6)) | I6: =IF($G6="","",_xlfn.MINIFS($E$5:$E$1504,$A$5:$A$1504,$A6,$D$5:$D$1504,"تسليم",$E$5:$E$1504,">"&$E6)) | J6: =IF($G6="","",IF(H6>0,IF(I6>0,MIN(H6,I6),H6),IF(I6>0,I6,تاريخ_الاحتساب))) | K6: =IF($G6="","",IF(AND(H6=0,I6=0),"جارية","مغلقة")) | L6: =IF($G6="","",MAX(0,NETWORKDAYS.INTL($E6,J6,رمز_العطلة,أيام_الأجازات)-1)) | M6: =IF($G6="","",MAX(0,L6-مهلة_المراجعة)) | N6: =IF($A6="",IF(OR($D6<>"",$E6<>""),"رقم المخرج ناقص",""),IF(ISNA(MATCH($A6,قائمة_المخرجات,0)),"رقم مخرج غير موجود",IF($D6="","نوع الحركة ناقص",IF(NOT(ISNUMBER($E6)),"التاريخ ناقص",IF($E6>تاريخ_الاحتساب,"تاريخ بعد تاريخ الاحتساب",IF(AND($D6<>"تسليم",COUNTIFS($A$5:$A$1504,$A6,$D$5:$D$1504,"تسليم",$E$5:$E$1504,"<="&$E6)=0),"لا يوجد تسليم قبل الحركة دي",""))))))
A7: D-002 | B7: =IF($A7="","",IFERROR(INDEX(مخرج_البند,MATCH($A7,قائمة_المخرجات,0)),"")) -> 1 | C7: =IF($A7="","",IFERROR(INDEX(مخرج_الوصف,MATCH($A7,قائمة_المخرجات,0)),"")) -> الخطة التفصيلية للمشروع | D7: تسليم | E7: 45698 | G7: =IF(OR($A7="",$D7<>"تسليم",NOT(ISNUMBER($E7))),"",COUNTIFS($A$5:$A$1504,$A7,$D$5:$D$1504,"تسليم",$E$5:$E$1504,"<"&$E7)+1) -> 1 | H7: =IF($G7="","",_xlfn.MINIFS($E$5:$E$1504,$A$5:$A$1504,$A7,$D$5:$D$1504,"<>تسليم",$E$5:$E$1504,">="&$E7)) -> 45721 | I7: =IF($G7="","",_xlfn.MINIFS($E$5:$E$1504,$A$5:$A$1504,$A7,$D$5:$D$1504,"تسليم",$E$5:$E$1504,">"&$E7)) -> 45728 | J7: =IF($G7="","",IF(H7>0,IF(I7>0,MIN(H7,I7),H7),IF(I7>0,I7,تاريخ_الاحتساب))) -> 45721 | K7: =IF($G7="","",IF(AND(H7=0,I7=0),"جارية","مغلقة")) -> مغلقة | L7: =IF($G7="","",MAX(0,NETWORKDAYS.INTL($E7,J7,رمز_العطلة,أيام_الأجازات)-1)) -> 17 | M7: =IF($G7="","",MAX(0,L7-مهلة_المراجعة)) -> 7 | N7: =IF($A7="",IF(OR($D7<>"",$E7<>""),"رقم المخرج ناقص",""),IF(ISNA(MATCH($A7,قائمة_المخرجات,0)),"رقم مخرج غير موجود",IF($D7="","نوع الحركة ناقص",IF(NOT(ISNUMBER($E7)),"التاريخ ناقص",IF($E7>تاريخ_الاحتساب,"تاريخ بعد تاريخ الاحتساب",IF(AND($D7<>"تسليم",COUNTIFS($A$5:$A$1504,$A7,$D$5:$D$1504,"تسليم",$E$5:$E$1504,"<="&$E7)=0),"لا يوجد تسليم قبل الحركة دي",""))))))
A8: D-002 | B8: =IF($A8="","",IFERROR(INDEX(مخرج_البند,MATCH($A8,قائمة_المخرجات,0)),"")) -> 1 | C8: =IF($A8="","",IFERROR(INDEX(مخرج_الوصف,MATCH($A8,قائمة_المخرجات,0)),"")) -> الخطة التفصيلية للمشروع | D8: رد بملاحظات | E8: 45721 | G8: =IF(OR($A8="",$D8<>"تسليم",NOT(ISNUMBER($E8))),"",COUNTIFS($A$5:$A$1504,$A8,$D$5:$D$1504,"تسليم",$E$5:$E$1504,"<"&$E8)+1) | H8: =IF($G8="","",_xlfn.MINIFS($E$5:$E$1504,$A$5:$A$1504,$A8,$D$5:$D$1504,"<>تسليم",$E$5:$E$1504,">="&$E8)) | I8: =IF($G8="","",_xlfn.MINIFS($E$5:$E$1504,$A$5:$A$1504,$A8,$D$5:$D$1504,"تسليم",$E$5:$E$1504,">"&$E8)) | J8: =IF($G8="","",IF(H8>0,IF(I8>0,MIN(H8,I8),H8),IF(I8>0,I8,تاريخ_الاحتساب))) | K8: =IF($G8="","",IF(AND(H8=0,I8=0),"جارية","مغلقة")) | L8: =IF($G8="","",MAX(0,NETWORKDAYS.INTL($E8,J8,رمز_العطلة,أيام_الأجازات)-1)) | M8: =IF($G8="","",MAX(0,L8-مهلة_المراجعة)) | N8: =IF($A8="",IF(OR($D8<>"",$E8<>""),"رقم المخرج ناقص",""),IF(ISNA(MATCH($A8,قائمة_المخرجات,0)),"رقم مخرج غير موجود",IF($D8="","نوع الحركة ناقص",IF(NOT(ISNUMBER($E8)),"التاريخ ناقص",IF($E8>تاريخ_الاحتساب,"تاريخ بعد تاريخ الاحتساب",IF(AND($D8<>"تسليم",COUNTIFS($A$5:$A$1504,$A8,$D$5:$D$1504,"تسليم",$E$5:$E$1504,"<="&$E8)=0),"لا يوجد تسليم قبل الحركة دي",""))))))
A9: D-002 | B9: =IF($A9="","",IFERROR(INDEX(مخرج_البند,MATCH($A9,قائمة_المخرجات,0)),"")) -> 1 | C9: =IF($A9="","",IFERROR(INDEX(مخرج_الوصف,MATCH($A9,قائمة_المخرجات,0)),"")) -> الخطة التفصيلية للمشروع | D9: تسليم | E9: 45728 | G9: =IF(OR($A9="",$D9<>"تسليم",NOT(ISNUMBER($E9))),"",COUNTIFS($A$5:$A$1504,$A9,$D$5:$D$1504,"تسليم",$E$5:$E$1504,"<"&$E9)+1) -> 2 | H9: =IF($G9="","",_xlfn.MINIFS($E$5:$E$1504,$A$5:$A$1504,$A9,$D$5:$D$1504,"<>تسليم",$E$5:$E$1504,">="&$E9)) -> 45736 | I9: =IF($G9="","",_xlfn.MINIFS($E$5:$E$1504,$A$5:$A$1504,$A9,$D$5:$D$1504,"تسليم",$E$5:$E$1504,">"&$E9)) -> 0 | J9: =IF($G9="","",IF(H9>0,IF(I9>0,MIN(H9,I9),H9),IF(I9>0,I9,تاريخ_الاحتساب))) -> 45736 | K9: =IF($G9="","",IF(AND(H9=0,I9=0),"جارية","مغلقة")) -> مغلقة | L9: =IF($G9="","",MAX(0,NETWORKDAYS.INTL($E9,J9,رمز_العطلة,أيام_الأجازات)-1)) -> 6 | M9: =IF($G9="","",MAX(0,L9-مهلة_المراجعة)) -> 0 | N9: =IF($A9="",IF(OR($D9<>"",$E9<>""),"رقم المخرج ناقص",""),IF(ISNA(MATCH($A9,قائمة_المخرجات,0)),"رقم مخرج غير موجود",IF($D9="","نوع الحركة ناقص",IF(NOT(ISNUMBER($E9)),"التاريخ ناقص",IF($E9>تاريخ_الاحتساب,"تاريخ بعد تاريخ الاحتساب",IF(AND($D9<>"تسليم",COUNTIFS($A$5:$A$1504,$A9,$D$5:$D$1504,"تسليم",$E$5:$E$1504,"<="&$E9)=0),"لا يوجد تسليم قبل الحركة دي",""))))))
A10: D-002 | B10: =IF($A10="","",IFERROR(INDEX(مخرج_البند,MATCH($A10,قائمة_المخرجات,0)),"")) -> 1 | C10: =IF($A10="","",IFERROR(INDEX(مخرج_الوصف,MATCH($A10,قائمة_المخرجات,0)),"")) -> الخطة التفصيلية للمشروع | D10: قبول | E10: 45736 | G10: =IF(OR($A10="",$D10<>"تسليم",NOT(ISNUMBER($E10))),"",COUNTIFS($A$5:$A$1504,$A10,$D$5:$D$1504,"تسليم",$E$5:$E$1504,"<"&$E10)+1) | H10: =IF($G10="","",_xlfn.MINIFS($E$5:$E$1504,$A$5:$A$1504,$A10,$D$5:$D$1504,"<>تسليم",$E$5:$E$1504,">="&$E10)) | I10: =IF($G10="","",_xlfn.MINIFS($E$5:$E$1504,$A$5:$A$1504,$A10,$D$5:$D$1504,"تسليم",$E$5:$E$1504,">"&$E10)) | J10: =IF($G10="","",IF(H10>0,IF(I10>0,MIN(H10,I10),H10),IF(I10>0,I10,تاريخ_الاحتساب))) | K10: =IF($G10="","",IF(AND(H10=0,I10=0),"جارية","مغلقة")) | L10: =IF($G10="","",MAX(0,NETWORKDAYS.INTL($E10,J10,رمز_العطلة,أيام_الأجازات)-1)) | M10: =IF($G10="","",MAX(0,L10-مهلة_المراجعة)) | N10: =IF($A10="",IF(OR($D10<>"",$E10<>""),"رقم المخرج ناقص",""),IF(ISNA(MATCH($A10,قائمة_المخرجات,0)),"رقم مخرج غير موجود",IF($D10="","نوع الحركة ناقص",IF(NOT(ISNUMBER($E10)),"التاريخ ناقص",IF($E10>تاريخ_الاحتساب,"تاريخ بعد تاريخ الاحتساب",IF(AND($D10<>"تسليم",COUNTIFS($A$5:$A$1504,$A10,$D$5:$D$1504,"تسليم",$E$5:$E$1504,"<="&$E10)=0),"لا يوجد تسليم قبل الحركة دي",""))))))
A11: D-003 | B11: =IF($A11="","",IFERROR(INDEX(مخرج_البند,MATCH($A11,قائمة_المخرجات,0)),"")) -> 2 | C11: =IF($A11="","",IFERROR(INDEX(مخرج_الوصف,MATCH($A11,قائمة_المخرجات,0)),"")) -> وثيقة متطلبات - الدفعة 1 | D11: تسليم | E11: 46082 | G11: =IF(OR($A11="",$D11<>"تسليم",NOT(ISNUMBER($E11))),"",COUNTIFS($A$5:$A$1504,$A11,$D$5:$D$1504,"تسليم",$E$5:$E$1504,"<"&$E11)+1) -> 1 | H11: =IF($G11="","",_xlfn.MINIFS($E$5:$E$1504,$A$5:$A$1504,$A11,$D$5:$D$1504,"<>تسليم",$E$5:$E$1504,">="&$E11)) -> 46127 | I11: =IF($G11="","",_xlfn.MINIFS($E$5:$E$1504,$A$5:$A$1504,$A11,$D$5:$D$1504,"تسليم",$E$5:$E$1504,">"&$E11)) -> 0 | J11: =IF($G11="","",IF(H11>0,IF(I11>0,MIN(H11,I11),H11),IF(I11>0,I11,تاريخ_الاحتساب))) -> 46127 | K11: =IF($G11="","",IF(AND(H11=0,I11=0),"جارية","مغلقة")) -> مغلقة | L11: =IF($G11="","",MAX(0,NETWORKDAYS.INTL($E11,J11,رمز_العطلة,أيام_الأجازات)-1)) -> 31 | M11: =IF($G11="","",MAX(0,L11-مهلة_المراجعة)) -> 21 | N11: =IF($A11="",IF(OR($D11<>"",$E11<>""),"رقم المخرج ناقص",""),IF(ISNA(MATCH($A11,قائمة_المخرجات,0)),"رقم مخرج غير موجود",IF($D11="","نوع الحركة ناقص",IF(NOT(ISNUMBER($E11)),"التاريخ ناقص",IF($E11>تاريخ_الاحتساب,"تاريخ بعد تاريخ الاحتساب",IF(AND($D11<>"تسليم",COUNTIFS($A$5:$A$1504,$A11,$D$5:$D$1504,"تسليم",$E$5:$E$1504,"<="&$E11)=0),"لا يوجد تسليم قبل الحركة دي",""))))))
A12: D-003 | B12: =IF($A12="","",IFERROR(INDEX(مخرج_البند,MATCH($A12,قائمة_المخرجات,0)),"")) -> 2 | C12: =IF($A12="","",IFERROR(INDEX(مخرج_الوصف,MATCH($A12,قائمة_المخرجات,0)),"")) -> وثيقة متطلبات - الدفعة 1 | D12: رد بملاحظات | E12: 46127 | G12: =IF(OR($A12="",$D12<>"تسليم",NOT(ISNUMBER($E12))),"",COUNTIFS($A$5:$A$1504,$A12,$D$5:$D$1504,"تسليم",$E$5:$E$1504,"<"&$E12)+1) | H12: =IF($G12="","",_xlfn.MINIFS($E$5:$E$1504,$A$5:$A$1504,$A12,$D$5:$D$1504,"<>تسليم",$E$5:$E$1504,">="&$E12)) | I12: =IF($G12="","",_xlfn.MINIFS($E$5:$E$1504,$A$5:$A$1504,$A12,$D$5:$D$1504,"تسليم",$E$5:$E$1504,">"&$E12)) | J12: =IF($G12="","",IF(H12>0,IF(I12>0,MIN(H12,I12),H12),IF(I12>0,I12,تاريخ_الاحتساب))) | K12: =IF($G12="","",IF(AND(H12=0,I12=0),"جارية","مغلقة")) | L12: =IF($G12="","",MAX(0,NETWORKDAYS.INTL($E12,J12,رمز_العطلة,أيام_الأجازات)-1)) | M12: =IF($G12="","",MAX(0,L12-مهلة_المراجعة)) | N12: =IF($A12="",IF(OR($D12<>"",$E12<>""),"رقم المخرج ناقص",""),IF(ISNA(MATCH($A12,قائمة_المخرجات,0)),"رقم مخرج غير موجود",IF($D12="","نوع الحركة ناقص",IF(NOT(ISNUMBER($E12)),"التاريخ ناقص",IF($E12>تاريخ_الاحتساب,"تاريخ بعد تاريخ الاحتساب",IF(AND($D12<>"تسليم",COUNTIFS($A$5:$A$1504,$A12,$D$5:$D$1504,"تسليم",$E$5:$E$1504,"<="&$E12)=0),"لا يوجد تسليم قبل الحركة دي",""))))))
A13: D-004 | B13: =IF($A13="","",IFERROR(INDEX(مخرج_البند,MATCH($A13,قائمة_المخرجات,0)),"")) -> 2 | C13: =IF($A13="","",IFERROR(INDEX(مخرج_الوصف,MATCH($A13,قائمة_المخرجات,0)),"")) -> وثيقة متطلبات - الدفعة 2 | D13: تسليم | E13: 46054 | G13: =IF(OR($A13="",$D13<>"تسليم",NOT(ISNUMBER($E13))),"",COUNTIFS($A$5:$A$1504,$A13,$D$5:$D$1504,"تسليم",$E$5:$E$1504,"<"&$E13)+1) -> 1 | H13: =IF($G13="","",_xlfn.MINIFS($E$5:$E$1504,$A$5:$A$1504,$A13,$D$5:$D$1504,"<>تسليم",$E$5:$E$1504,">="&$E13)) -> 0 | I13: =IF($G13="","",_xlfn.MINIFS($E$5:$E$1504,$A$5:$A$1504,$A13,$D$5:$D$1504,"تسليم",$E$5:$E$1504,">"&$E13)) -> 46152 | J13: =IF($G13="","",IF(H13>0,IF(I13>0,MIN(H13,I13),H13),IF(I13>0,I13,تاريخ_الاحتساب))) -> 46152 | K13: =IF($G13="","",IF(AND(H13=0,I13=0),"جارية","مغلقة")) -> مغلقة | L13: =IF($G13="","",MAX(0,NETWORKDAYS.INTL($E13,J13,رمز_العطلة,أيام_الأجازات)-1)) -> 67 | M13: =IF($G13="","",MAX(0,L13-مهلة_المراجعة)) -> 57 | N13: =IF($A13="",IF(OR($D13<>"",$E13<>""),"رقم المخرج ناقص",""),IF(ISNA(MATCH($A13,قائمة_المخرجات,0)),"رقم مخرج غير موجود",IF($D13="","نوع الحركة ناقص",IF(NOT(ISNUMBER($E13)),"التاريخ ناقص",IF($E13>تاريخ_الاحتساب,"تاريخ بعد تاريخ الاحتساب",IF(AND($D13<>"تسليم",COUNTIFS($A$5:$A$1504,$A13,$D$5:$D$1504,"تسليم",$E$5:$E$1504,"<="&$E13)=0),"لا يوجد تسليم قبل الحركة دي",""))))))
A14: D-004 | B14: =IF($A14="","",IFERROR(INDEX(مخرج_البند,MATCH($A14,قائمة_المخرجات,0)),"")) -> 2 | C14: =IF($A14="","",IFERROR(INDEX(مخرج_الوصف,MATCH($A14,قائمة_المخرجات,0)),"")) -> وثيقة متطلبات - الدفعة 2 | D14: تسليم | E14: 46152 | G14: =IF(OR($A14="",$D14<>"تسليم",NOT(ISNUMBER($E14))),"",COUNTIFS($A$5:$A$1504,$A14,$D$5:$D$1504,"تسليم",$E$5:$E$1504,"<"&$E14)+1) -> 2 | H14: =IF($G14="","",_xlfn.MINIFS($E$5:$E$1504,$A$5:$A$1504,$A14,$D$5:$D$1504,"<>تسليم",$E$5:$E$1504,">="&$E14)) -> 0 | I14: =IF($G14="","",_xlfn.MINIFS($E$5:$E$1504,$A$5:$A$1504,$A14,$D$5:$D$1504,"تسليم",$E$5:$E$1504,">"&$E14)) -> 0 | J14: =IF($G14="","",IF(H14>0,IF(I14>0,MIN(H14,I14),H14),IF(I14>0,I14,تاريخ_الاحتساب))) -> 46203 | K14: =IF($G14="","",IF(AND(H14=0,I14=0),"جارية","مغلقة")) -> جارية | L14: =IF($G14="","",MAX(0,NETWORKDAYS.INTL($E14,J14,رمز_العطلة,أيام_الأجازات)-1)) -> 34 | M14: =IF($G14="","",MAX(0,L14-مهلة_المراجعة)) -> 24 | N14: =IF($A14="",IF(OR($D14<>"",$E14<>""),"رقم المخرج ناقص",""),IF(ISNA(MATCH($A14,قائمة_المخرجات,0)),"رقم مخرج غير موجود",IF($D14="","نوع الحركة ناقص",IF(NOT(ISNUMBER($E14)),"التاريخ ناقص",IF($E14>تاريخ_الاحتساب,"تاريخ بعد تاريخ الاحتساب",IF(AND($D14<>"تسليم",COUNTIFS($A$5:$A$1504,$A14,$D$5:$D$1504,"تسليم",$E$5:$E$1504,"<="&$E14)=0),"لا يوجد تسليم قبل الحركة دي",""))))))
A15: D-007 | B15: =IF($A15="","",IFERROR(INDEX(مخرج_البند,MATCH($A15,قائمة_المخرجات,0)),"")) -> 3.أ | C15: =IF($A15="","",IFERROR(INDEX(مخرج_الوصف,MATCH($A15,قائمة_المخرجات,0)),"")) -> تقرير تطوير الخدمات 1 | D15: تسليم | E15: 46174 | G15: =IF(OR($A15="",$D15<>"تسليم",NOT(ISNUMBER($E15))),"",COUNTIFS($A$5:$A$1504,$A15,$D$5:$D$1504,"تسليم",$E$5:$E$1504,"<"&$E15)+1) -> 1 | H15: =IF($G15="","",_xlfn.MINIFS($E$5:$E$1504,$A$5:$A$1504,$A15,$D$5:$D$1504,"<>تسليم",$E$5:$E$1504,">="&$E15)) -> 0 | I15: =IF($G15="","",_xlfn.MINIFS($E$5:$E$1504,$A$5:$A$1504,$A15,$D$5:$D$1504,"تسليم",$E$5:$E$1504,">"&$E15)) -> 0 | J15: =IF($G15="","",IF(H15>0,IF(I15>0,MIN(H15,I15),H15),IF(I15>0,I15,تاريخ_الاحتساب))) -> 46203 | K15: =IF($G15="","",IF(AND(H15=0,I15=0),"جارية","مغلقة")) -> جارية | L15: =IF($G15="","",MAX(0,NETWORKDAYS.INTL($E15,J15,رمز_العطلة,أيام_الأجازات)-1)) -> 21 | M15: =IF($G15="","",MAX(0,L15-مهلة_المراجعة)) -> 11 | N15: =IF($A15="",IF(OR($D15<>"",$E15<>""),"رقم المخرج ناقص",""),IF(ISNA(MATCH($A15,قائمة_المخرجات,0)),"رقم مخرج غير موجود",IF($D15="","نوع الحركة ناقص",IF(NOT(ISNUMBER($E15)),"التاريخ ناقص",IF($E15>تاريخ_الاحتساب,"تاريخ بعد تاريخ الاحتساب",IF(AND($D15<>"تسليم",COUNTIFS($A$5:$A$1504,$A15,$D$5:$D$1504,"تسليم",$E$5:$E$1504,"<="&$E15)=0),"لا يوجد تسليم قبل الحركة دي",""))))))
B16: =IF($A16="","",IFERROR(INDEX(مخرج_البند,MATCH($A16,قائمة_المخرجات,0)),"")) | C16: =IF($A16="","",IFERROR(INDEX(مخرج_الوصف,MATCH($A16,قائمة_المخرجات,0)),"")) | G16: =IF(OR($A16="",$D16<>"تسليم",NOT(ISNUMBER($E16))),"",COUNTIFS($A$5:$A$1504,$A16,$D$5:$D$1504,"تسليم",$E$5:$E$1504,"<"&$E16)+1) | H16: =IF($G16="","",_xlfn.MINIFS($E$5:$E$1504,$A$5:$A$1504,$A16,$D$5:$D$1504,"<>تسليم",$E$5:$E$1504,">="&$E16)) | I16: =IF($G16="","",_xlfn.MINIFS($E$5:$E$1504,$A$5:$A$1504,$A16,$D$5:$D$1504,"تسليم",$E$5:$E$1504,">"&$E16)) | J16: =IF($G16="","",IF(H16>0,IF(I16>0,MIN(H16,I16),H16),IF(I16>0,I16,تاريخ_الاحتساب))) | K16: =IF($G16="","",IF(AND(H16=0,I16=0),"جارية","مغلقة")) | L16: =IF($G16="","",MAX(0,NETWORKDAYS.INTL($E16,J16,رمز_العطلة,أيام_الأجازات)-1)) | M16: =IF($G16="","",MAX(0,L16-مهلة_المراجعة)) | N16: =IF($A16="",IF(OR($D16<>"",$E16<>""),"رقم المخرج ناقص",""),IF(ISNA(MATCH($A16,قائمة_المخرجات,0)),"رقم مخرج غير موجود",IF($D16="","نوع الحركة ناقص",IF(NOT(ISNUMBER($E16)),"التاريخ ناقص",IF($E16>تاريخ_الاحتساب,"تاريخ بعد تاريخ الاحتساب",IF(AND($D16<>"تسليم",COUNTIFS($A$5:$A$1504,$A16,$D$5:$D$1504,"تسليم",$E$5:$E$1504,"<="&$E16)=0),"لا يوجد تسليم قبل الحركة دي",""))))))
